<!--
      ===============================================================================
      This file was created by hand by PUMAS_TEAM,
      we are using the stl files provide by TMC pakages.
      Author: Edd-2 
      ===============================================================================
  -->

<robot name="hsrb_pumas">
  <!-- Base links -->
   <link name="base_link">
    <visual>
      <geometry>
        <mesh filename="package://knowledge/hardware/robot_descrptions/hsrb/base_v2/base_light.dae"/>
      </geometry>
    </visual>
    <visual>
      <geometry>
        <mesh filename="package://knowledge/hardware/robot_descrptions/hsrb/base_v2/body_light.dae"/>
      </geometry>
    </visual>
    <visual>
      <geometry>
        <mesh filename="package://knowledge/hardware/robot_descrptions/hsrb/base_v2/torso_base.dae"/>
      </geometry>
    </visual>
    <collision>
      <geometry>
        <mesh filename="package://knowledge/hardware/robot_descrptions/hsrb/base_v2/base.stl"/>
      </geometry>
    </collision>
  </link>

  <!-- Laser links -->
  <link name="laser_link">
    <visual>
      <geometry>
        <mesh filename="package://knowledge/hardware/robot_descrptions/hsrb/sensors/laser.dae"/>
      </geometry>
    </visual>
    <collision>
      <geometry>
        <mesh filename="package://knowledge/hardware/robot_descrptions/hsrb/sensors/laser.stl"/>
      </geometry>
    </collision>
  </link>
  <joint name="base_range_sensor_joint" type="fixed">
    <origin rpy="0.0 0.0 0.0" xyz="0.1675 0.0 0.1844"/>
    <parent link="base_link"/>
    <child link="laser_link"/>
  </joint>

  <!-- Bumper links -->

  <link name="base_f_bumper_link">
    <visual>
      <geometry>
        <mesh filename="package://knowledge/hardware/robot_descrptions/hsrb/base_v2/bumper.dae"/>
      </geometry>
    </visual>
    <collision>
      <geometry>
        <mesh filename="package://knowledge/hardware/robot_descrptions/hsrb/base_v2/bumper.stl"/>
      </geometry>
    </collision>
  </link>
  <link name="base_b_bumper_link">
    <visual>
      <geometry>
        <mesh filename="package://knowledge/hardware/robot_descrptions/hsrb/base_v2/bumper.dae"/>
      </geometry>
    </visual>
    <collision>
      <geometry>
        <mesh filename="package://knowledge/hardware/robot_descrptions/hsrb/base_v2/bumper.stl"/>
      </geometry>
    </collision>
  </link>

  <joint name="base_b_bumper_joint" type="revolute">
    <origin rpy="0.0 0.0 3.14159265359" xyz="0.0 0.0013 0.0"/>
    <parent link="base_link"/>
    <child link="base_b_bumper_link"/>
    <limit effort="0" lower="0" upper="0" velocity="0"/>
  </joint>
  
  <joint name="base_f_bumper_joint" type="revolute">
    <origin rpy="0.0 0.0 0.0" xyz="0.0 0.0 0.0"/>
    <parent link="base_link"/>
    <child link="base_f_bumper_link"/>
    <limit effort="0" lower="0" upper="0" velocity="0"/>
  </joint>

  <!--
    ==============================================
                  TORSO LINKS
  -->
  <!--
  <link name="torso_lift_link">
    <visual>
      <geometry>
        <mesh filename="package://hsrb_description/meshes/torso_v0/torso_light.dae"/>
      </geometry>
    </visual>
    <collision>
      <geometry>
        <mesh filename="package://hsrb_description/meshes/torso_v0/torso.stl"/>
      </geometry>
    </collision>
  </link>
  -->

<!--
<link name="torso_lift_link">
   <visual>
      <origin xyz= "-0.01 0 0" rpy="0 0 0"/>
      <geometry><box size="0.06 0.04 0.04"/></geometry>
      <material name="black"><color rgba="0.2 0.2 0.2 1"/></material>
    </visual>
  </link>

  <joint name="torso_lift_joint" type="prismatic">
    <origin rpy="0.0 0.0 0.0" xyz="0.0 0.0 0.752"/>
    <axis xyz="0.0 0.0 1.0"/>
    <limit effort="300.0" lower="0.0" upper="0.345" velocity="0.1"/>
    <parent link="base_link"/>
    <child link="torso_lift_link"/>
    <mimic joint="arm_lift_joint" multiplier="0.5"/> 
  </joint>
  -->

<!--
  <link name="arm_lift_link">
    <visual>
      <geometry>
        <mesh filename="package://hsrb_description/meshes/arm_v0/shoulder.dae"/>
      </geometry>
    </visual>
    <collision>
      <geometry>
        <mesh filename="package://hsrb_description/meshes/arm_v0/shoulder.stl"/>
      </geometry>
    </collision>
  </link>
-->

  <link name="arm_lift_link">
   <visual>
      <origin xyz= "-0.01 0 0" rpy="0 0 0"/>
      <geometry><box size="0.06 0.04 0.04"/></geometry>
      <material name="black"><color rgba="0.2 0.2 0.2 1"/></material>
    </visual>
  </link>

   <joint name="arm_lift_joint" type="prismatic">
    <origin rpy="0.0 0.0 0.0" xyz="0.0 0.0 0.340"/>
    <axis xyz="0.0 0.0 1.0"/>
    <limit effort="300.0" lower="0.0" upper="0.69" velocity="0.2"/>
    <parent link="base_link"/>
    <child link="arm_lift_link"/>
  </joint>


</robot>
