<sdf version='1.6'>
  <world name='default'>
    <physics name='default_physics' default='0' type='ode'>
      <max_step_size>0.001</max_step_size>
      <real_time_factor>1</real_time_factor>
      <real_time_update_rate>1000</real_time_update_rate>
    </physics>
    <light name='sun' type='directional'>
      <cast_shadows>1</cast_shadows>
      <pose frame=''>0 0 10 0 -0 0</pose>
      <diffuse>0.8 0.8 0.8 1</diffuse>
      <specular>0.2 0.2 0.2 1</specular>
      <attenuation>
        <range>1000</range>
        <constant>0.9</constant>
        <linear>0.01</linear>
        <quadratic>0.001</quadratic>
      </attenuation>
      <direction>-0.5 0.1 -0.9</direction>
    </light>
    <model name='ground_plane'>
      <static>1</static>
      <link name='link'>
        <collision name='collision'>
          <geometry>
            <plane>
              <normal>0 0 1</normal>
              <size>100 100</size>
            </plane>
          </geometry>
          <surface>
            <friction>
              <ode>
                <mu>100</mu>
                <mu2>50</mu2>
              </ode>
              <torsional>
                <ode/>
              </torsional>
            </friction>
            <contact>
              <ode/>
            </contact>
            <bounce/>
          </surface>
          <max_contacts>10</max_contacts>
        </collision>
        <visual name='visual'>
          <cast_shadows>0</cast_shadows>
          <geometry>
            <plane>
              <normal>0 0 1</normal>
              <size>100 100</size>
            </plane>
          </geometry>
          <material>
            <script>
              <uri>file://media/materials/scripts/gazebo.material</uri>
              <name>Gazebo/Grey</name>
            </script>
          </material>
        </visual>
        <self_collide>0</self_collide>
        <kinematic>0</kinematic>
      </link>
    </model>
    <gravity>0 0 -9.8</gravity>
    <magnetic_field>6e-06 2.3e-05 -4.2e-05</magnetic_field>
    <atmosphere type='adiabatic'/>
    <scene>
      <ambient>0.4 0.4 0.4 1</ambient>
      <background>0.7 0.7 0.7 1</background>
      <shadows>1</shadows>
    </scene>
    <spherical_coordinates>
      <surface_model>EARTH_WGS84</surface_model>
      <latitude_deg>0</latitude_deg>
      <longitude_deg>0</longitude_deg>
      <elevation>0</elevation>
      <heading_deg>0</heading_deg>
    </spherical_coordinates>
    <model name='hsrb'>
      <link name='base_footprint'>
        <pose frame=''>0 0 0 0 -0 0</pose>
        <inertial>
          <pose frame=''>-0.025934 -0.00547 0.176333 0 -0 0</pose>
          <mass>50.02</mass>
          <inertia>
            <ixx>0.376384</ixx>
            <ixy>0.000387825</ixy>
            <ixz>0.0308632</ixz>
            <iyy>0.345982</iyy>
            <iyz>0.0177433</iyz>
            <izz>0.153464</izz>
          </inertia>
        </inertial>
        <collision name='base_footprint_fixed_joint_lump__base_link_collision'>
          <pose frame=''>0 0 0 0 -0 0</pose>
          <geometry>
            <mesh>
              <scale>1 1 1</scale>
              <uri>/opt/ros/kinetic/share/hsrb_description/meshes/base_v2/base.stl</uri>
            </mesh>
          </geometry>
          <surface>
            <contact>
              <ode/>
            </contact>
            <friction>
              <ode>
                <mu>0.9</mu>
                <mu2>0.9</mu2>
              </ode>
              <torsional>
                <ode/>
              </torsional>
            </friction>
            <bounce/>
          </surface>
          <max_contacts>10</max_contacts>
        </collision>
        <collision name='base_footprint_fixed_joint_lump__base_range_sensor_link_collision_1'>
          <pose frame=''>0.1675 0 0.1844 0 -0 0</pose>
          <geometry>
            <mesh>
              <scale>1 1 1</scale>
              <uri>/opt/ros/kinetic/share/hsrb_parts_description/meshes/sensors/laser.stl</uri>
            </mesh>
          </geometry>
          <surface>
            <contact>
              <ode/>
            </contact>
            <friction>
              <ode>
                <mu>0.9</mu>
                <mu2>0.9</mu2>
              </ode>
              <torsional>
                <ode/>
              </torsional>
            </friction>
            <bounce/>
          </surface>
          <max_contacts>10</max_contacts>
        </collision>
        <visual name='base_footprint_fixed_joint_lump__base_link_visual'>
          <pose frame=''>0 0 0 0 -0 0</pose>
          <geometry>
            <mesh>
              <scale>1 1 1</scale>
              <uri>/opt/ros/kinetic/share/hsrb_description/meshes/base_v2/base_light.dae</uri>
            </mesh>
          </geometry>
          <material>
            <script>
              <uri>__default__</uri>
              <name>__default__</name>
            </script>
          </material>
        </visual>
        <visual name='base_footprint_fixed_joint_lump__base_link_visual_1'>
          <pose frame=''>0 0 0 0 -0 0</pose>
          <geometry>
            <mesh>
              <scale>1 1 1</scale>
              <uri>/opt/ros/kinetic/share/hsrb_description/meshes/base_v2/body_light.dae</uri>
            </mesh>
          </geometry>
          <material>
            <script>
              <uri>__default__</uri>
              <name>__default__</name>
            </script>
          </material>
        </visual>
        <visual name='base_footprint_fixed_joint_lump__base_link_visual_2'>
          <pose frame=''>0 0 0 0 -0 0</pose>
          <geometry>
            <mesh>
              <scale>1 1 1</scale>
              <uri>/opt/ros/kinetic/share/hsrb_description/meshes/base_v2/torso_base.dae</uri>
            </mesh>
          </geometry>
          <material>
            <script>
              <uri>__default__</uri>
              <name>__default__</name>
            </script>
          </material>
        </visual>
        <visual name='base_footprint_fixed_joint_lump__base_range_sensor_link_visual_3'>
          <pose frame=''>0.1675 0 0.1844 0 -0 0</pose>
          <geometry>
            <mesh>
              <scale>1 1 1</scale>
              <uri>/opt/ros/kinetic/share/hsrb_parts_description/meshes/sensors/laser.dae</uri>
            </mesh>
          </geometry>
          <material>
            <script>
              <uri>__default__</uri>
              <name>__default__</name>
            </script>
          </material>
        </visual>
        <velocity_decay/>
        <velocity_decay/>
        <sensor name='base_imu' type='imu'>
          <update_rate>10</update_rate>
          <plugin name='base_imu_plugin' filename='libgazebo_ros_imu_sensor.so'>
            <updateRateHZ>50.0</updateRateHZ>
            <bodyName>base_link</bodyName>
            <topicName>hsrb/base_imu/data</topicName>
            <frameName>base_imu_frame</frameName>
            <gaussianNoise>0.0</gaussianNoise>
            <xyzOffset>0.0 0.0 0.0</xyzOffset>
            <rpyOffset>0.0 -0.0 0.0</rpyOffset>
            <robotNamespace>/</robotNamespace>
          </plugin>
          <imu>
            <angular_velocity>
              <x>
                <noise type='gaussian'>
                  <mean>0</mean>
                  <stddev>0.0002</stddev>
                  <bias_mean>7.5e-06</bias_mean>
                  <bias_stddev>8e-07</bias_stddev>
                </noise>
              </x>
              <y>
                <noise type='gaussian'>
                  <mean>0</mean>
                  <stddev>0.0002</stddev>
                  <bias_mean>7.5e-06</bias_mean>
                  <bias_stddev>8e-07</bias_stddev>
                </noise>
              </y>
              <z>
                <noise type='gaussian'>
                  <mean>0</mean>
                  <stddev>0.0002</stddev>
                  <bias_mean>7.5e-06</bias_mean>
                  <bias_stddev>8e-07</bias_stddev>
                </noise>
              </z>
            </angular_velocity>
            <linear_acceleration>
              <x>
                <noise type='gaussian'>
                  <mean>0</mean>
                  <stddev>0.017</stddev>
                  <bias_mean>0.1</bias_mean>
                  <bias_stddev>0.001</bias_stddev>
                </noise>
              </x>
              <y>
                <noise type='gaussian'>
                  <mean>0</mean>
                  <stddev>0.017</stddev>
                  <bias_mean>0.1</bias_mean>
                  <bias_stddev>0.001</bias_stddev>
                </noise>
              </y>
              <z>
                <noise type='gaussian'>
                  <mean>0</mean>
                  <stddev>0.017</stddev>
                  <bias_mean>0.1</bias_mean>
                  <bias_stddev>0.001</bias_stddev>
                </noise>
              </z>
            </linear_acceleration>
          </imu>
          <pose frame=''>0.0005 0.1296 0.181 0 -0 0</pose>
        </sensor>
        <velocity_decay/>
        <gravity>1</gravity>
        <gravity>1</gravity>
        <velocity_decay/>
        <sensor name='base_range_sensor' type='ray'>
          <update_rate>30</update_rate>
          <visualize>0</visualize>
          <ray>
            <scan>
              <horizontal>
                <samples>721</samples>
                <resolution>1</resolution>
                <min_angle>-2.1</min_angle>
                <max_angle>2.1</max_angle>
              </horizontal>
              <vertical>
                <samples>1</samples>
                <min_angle>0</min_angle>
                <max_angle>0</max_angle>
              </vertical>
            </scan>
            <range>
              <min>0.05</min>
              <max>60</max>
              <resolution>0.001</resolution>
            </range>
          </ray>
          <plugin name='hokuyo_laser' filename='libgazebo_ros_laser.so'>
            <topicName>hsrb/base_scan</topicName>
            <frameName>base_range_sensor_link</frameName>
            <robotNamespace>/</robotNamespace>
          </plugin>
          <pose frame=''>0.1675 0 0.1844 0 -0 0</pose>
        </sensor>
        <gravity>1</gravity>
        <velocity_decay/>
        <self_collide>0</self_collide>
        <gravity>1</gravity>
        <kinematic>0</kinematic>
      </link>
      <link name='arm_lift_link'>
        <pose frame=''>0 0 0.34 0 -0 0</pose>
        <inertial>
          <pose frame=''>0.051549 0.042438 -0.064145 0 -0 0</pose>
          <mass>1.27582</mass>
          <inertia>
            <ixx>0.004633</ixx>
            <ixy>0.000475273</ixy>
            <ixz>-0.002403</ixz>
            <iyy>0.008065</iyy>
            <iyz>-0.000100269</iyz>
            <izz>0.007672</izz>
          </inertia>
        </inertial>
        <collision name='arm_lift_link_collision'>
          <pose frame=''>0 0 0 0 -0 0</pose>
          <geometry>
            <mesh>
              <scale>1 1 1</scale>
              <uri>/opt/ros/kinetic/share/hsrb_description/meshes/arm_v0/shoulder.stl</uri>
            </mesh>
          </geometry>
          <surface>
            <contact>
              <ode/>
            </contact>
            <friction>
              <ode>
                <mu>0.9</mu>
                <mu2>0.9</mu2>
              </ode>
              <torsional>
                <ode/>
              </torsional>
            </friction>
            <bounce/>
          </surface>
          <max_contacts>10</max_contacts>
        </collision>
        <visual name='arm_lift_link_visual'>
          <pose frame=''>0 0 0 0 -0 0</pose>
          <geometry>
            <mesh>
              <scale>1 1 1</scale>
              <uri>/opt/ros/kinetic/share/hsrb_description/meshes/arm_v0/shoulder.dae</uri>
            </mesh>
          </geometry>
          <material>
            <script>
              <uri>__default__</uri>
              <name>__default__</name>
            </script>
          </material>
        </visual>
        <gravity>1</gravity>
        <velocity_decay/>
        <self_collide>0</self_collide>
        <gravity>1</gravity>
        <kinematic>0</kinematic>
      </link>
      <joint name='arm_lift_joint' type='prismatic'>
        <child>arm_lift_link</child>
        <parent>base_footprint</parent>
        <axis>
          <xyz>0 0 1</xyz>
          <limit>
            <lower>0</lower>
            <upper>0.69</upper>
            <effort>300</effort>
            <velocity>0.2</velocity>
          </limit>
          <dynamics>
            <damping>1</damping>
            <friction>0</friction>
            <spring_reference>0</spring_reference>
            <spring_stiffness>0</spring_stiffness>
          </dynamics>
          <use_parent_model_frame>1</use_parent_model_frame>
        </axis>
        <physics>
          <ode>
            <limit>
              <cfm>0</cfm>
              <erp>0.2</erp>
            </limit>
          </ode>
        </physics>
      </joint>
      <link name='arm_flex_link'>
        <pose frame=''>0.141 0.078 0.34 0 -0 0</pose>
        <inertial>
          <pose frame=''>0.000632 0.006404 0.118529 0 -0 0</pose>
          <mass>1.33929</mass>
          <inertia>
            <ixx>7.528</ixx>
            <ixy>-2.02842e-05</ixy>
            <ixz>-2.29472e-05</ixz>
            <iyy>0.007102</iyy>
            <iyz>-9.17961e-05</iyz>
            <izz>0.001552</izz>
          </inertia>
        </inertial>
        <collision name='arm_flex_link_collision'>
          <pose frame=''>0 0 0 0 -0 0</pose>
          <geometry>
            <mesh>
              <scale>1 1 1</scale>
              <uri>/opt/ros/kinetic/share/hsrb_description/meshes/arm_v0/arm_flex.stl</uri>
            </mesh>
          </geometry>
          <surface>
            <contact>
              <ode/>
            </contact>
            <friction>
              <ode>
                <mu>0.9</mu>
                <mu2>0.9</mu2>
              </ode>
              <torsional>
                <ode/>
              </torsional>
            </friction>
            <bounce/>
          </surface>
          <max_contacts>10</max_contacts>
        </collision>
        <visual name='arm_flex_link_visual'>
          <pose frame=''>0 0 0 0 -0 0</pose>
          <geometry>
            <mesh>
              <scale>1 1 1</scale>
              <uri>/opt/ros/kinetic/share/hsrb_description/meshes/arm_v0/arm_flex_light.dae</uri>
            </mesh>
          </geometry>
          <material>
            <script>
              <uri>__default__</uri>
              <name>__default__</name>
            </script>
          </material>
        </visual>
        <gravity>1</gravity>
        <velocity_decay/>
        <self_collide>0</self_collide>
        <gravity>1</gravity>
        <kinematic>0</kinematic>
      </link>
      <joint name='arm_flex_joint' type='revolute'>
        <child>arm_flex_link</child>
        <parent>arm_lift_link</parent>
        <axis>
          <xyz>0 -1 0</xyz>
          <limit>
            <lower>-2.62</lower>
            <upper>0</upper>
            <effort>100</effort>
            <velocity>1.2</velocity>
          </limit>
          <dynamics>
            <damping>1</damping>
            <friction>0</friction>
            <spring_reference>0</spring_reference>
            <spring_stiffness>0</spring_stiffness>
          </dynamics>
          <use_parent_model_frame>1</use_parent_model_frame>
        </axis>
        <physics>
          <ode>
            <limit>
              <cfm>0</cfm>
              <erp>0.2</erp>
            </limit>
          </ode>
        </physics>
      </joint>
      <link name='arm_roll_link'>
        <pose frame=''>0.146 0.078 0.685 0 -0 0</pose>
        <inertial>
          <pose frame=''>-0.006927 0.002039 -0.064837 0 -0 0</pose>
          <mass>0.247936</mass>
          <inertia>
            <ixx>0.004267</ixx>
            <ixy>-1.83222e-05</ixy>
            <ixz>1.79845e-05</ixz>
            <iyy>0.000780924</iyy>
            <iyz>-1.39233e-05</iyz>
            <izz>0.00412</izz>
          </inertia>
        </inertial>
        <collision name='arm_roll_link_collision'>
          <pose frame=''>0 0 0 0 -0 0</pose>
          <geometry>
            <mesh>
              <scale>1 1 1</scale>
              <uri>/opt/ros/kinetic/share/hsrb_description/meshes/arm_v0/arm_roll.stl</uri>
            </mesh>
          </geometry>
          <surface>
            <contact>
              <ode/>
            </contact>
            <friction>
              <ode>
                <mu>0.9</mu>
                <mu2>0.9</mu2>
              </ode>
              <torsional>
                <ode/>
              </torsional>
            </friction>
            <bounce/>
          </surface>
          <max_contacts>10</max_contacts>
        </collision>
        <visual name='arm_roll_link_visual'>
          <pose frame=''>0 0 0 0 -0 0</pose>
          <geometry>
            <mesh>
              <scale>1 1 1</scale>
              <uri>/opt/ros/kinetic/share/hsrb_description/meshes/arm_v0/arm_roll_light.dae</uri>
            </mesh>
          </geometry>
          <material>
            <script>
              <uri>__default__</uri>
              <name>__default__</name>
            </script>
          </material>
        </visual>
        <gravity>1</gravity>
        <velocity_decay/>
        <self_collide>0</self_collide>
        <gravity>1</gravity>
        <kinematic>0</kinematic>
      </link>
      <joint name='arm_roll_joint' type='revolute'>
        <child>arm_roll_link</child>
        <parent>arm_flex_link</parent>
        <axis>
          <xyz>0 0 1</xyz>
          <limit>
            <lower>-2.09</lower>
            <upper>3.84</upper>
            <effort>100</effort>
            <velocity>2</velocity>
          </limit>
          <dynamics>
            <damping>0.1</damping>
            <friction>0</friction>
            <spring_reference>0</spring_reference>
            <spring_stiffness>0</spring_stiffness>
          </dynamics>
          <use_parent_model_frame>1</use_parent_model_frame>
        </axis>
        <physics>
          <ode>
            <limit>
              <cfm>0</cfm>
              <erp>0.2</erp>
            </limit>
          </ode>
        </physics>
      </joint>
      <link name='wrist_flex_link'>
        <pose frame=''>0.146 0.078 0.685 0 -0 0</pose>
        <inertial>
          <pose frame=''>0.000131 -0.003929 0.00217 0 -0 0</pose>
          <mass>0.681225</mass>
          <inertia>
            <ixx>7.43536e-05</ixx>
            <ixy>4.94515e-07</ixy>
            <ixz>2.2937e-08</ixz>
            <iyy>3.84329e-05</iyy>
            <iyz>-2.55576e-06</iyz>
            <izz>6.46809e-05</izz>
          </inertia>
        </inertial>
        <collision name='wrist_flex_link_collision'>
          <pose frame=''>0 0 0.03 0 -0 0</pose>
          <geometry>
            <cylinder>
              <length>0.04</length>
              <radius>0.017</radius>
            </cylinder>
          </geometry>
          <surface>
            <contact>
              <ode/>
            </contact>
            <friction>
              <ode>
                <mu>0.9</mu>
                <mu2>0.9</mu2>
              </ode>
              <torsional>
                <ode/>
              </torsional>
            </friction>
            <bounce/>
          </surface>
          <max_contacts>10</max_contacts>
        </collision>
        <visual name='wrist_flex_link_visual'>
          <pose frame=''>0 0 0 0 -0 0</pose>
          <geometry>
            <mesh>
              <scale>1 1 1</scale>
              <uri>/opt/ros/kinetic/share/hsrb_description/meshes/wrist_v0/wrist_flex.dae</uri>
            </mesh>
          </geometry>
          <material>
            <script>
              <uri>__default__</uri>
              <name>__default__</name>
            </script>
          </material>
        </visual>
        <visual name='wrist_flex_link_visual_1'>
          <pose frame=''>0 0 0.04 0 -0 0</pose>
          <geometry>
            <cylinder>
              <length>0.02</length>
              <radius>0.017</radius>
            </cylinder>
          </geometry>
          <material>
            <script>
              <uri>__default__</uri>
              <name>__default__</name>
            </script>
          </material>
        </visual>
        <gravity>1</gravity>
        <velocity_decay/>
        <self_collide>0</self_collide>
        <gravity>1</gravity>
        <kinematic>0</kinematic>
      </link>
      <joint name='wrist_flex_joint' type='revolute'>
        <child>wrist_flex_link</child>
        <parent>arm_roll_link</parent>
        <axis>
          <xyz>0 -1 0</xyz>
          <limit>
            <lower>-1.92</lower>
            <upper>1.22</upper>
            <effort>100</effort>
            <velocity>1.5</velocity>
          </limit>
          <dynamics>
            <damping>1</damping>
            <friction>0</friction>
            <spring_reference>0</spring_reference>
            <spring_stiffness>0</spring_stiffness>
          </dynamics>
          <use_parent_model_frame>1</use_parent_model_frame>
        </axis>
        <physics>
          <ode>
            <limit>
              <cfm>0</cfm>
              <erp>0.2</erp>
            </limit>
          </ode>
        </physics>
      </joint>
      <link name='wrist_ft_sensor_mount_link'>
        <pose frame=''>0.146 0.078 0.685 0 -0 0</pose>
        <inertial>
          <pose frame=''>0 0 0 0 -0 0</pose>
          <mass>0.01</mass>
          <inertia>
            <ixx>0.001</ixx>
            <ixy>0</ixy>
            <ixz>0</ixz>
            <iyy>0.001</iyy>
            <iyz>0</iyz>
            <izz>0.001</izz>
          </inertia>
        </inertial>
        <self_collide>0</self_collide>
        <kinematic>0</kinematic>
      </link>
      <joint name='wrist_roll_joint' type='revolute'>
        <child>wrist_ft_sensor_mount_link</child>
        <parent>wrist_flex_link</parent>
        <axis>
          <xyz>0 0 1</xyz>
          <limit>
            <lower>-1.92</lower>
            <upper>3.67</upper>
            <effort>100</effort>
            <velocity>1.5</velocity>
          </limit>
          <dynamics>
            <damping>1</damping>
            <friction>0</friction>
            <spring_reference>0</spring_reference>
            <spring_stiffness>0</spring_stiffness>
          </dynamics>
          <use_parent_model_frame>1</use_parent_model_frame>
        </axis>
        <physics>
          <ode>
            <limit>
              <cfm>0</cfm>
              <erp>0.2</erp>
            </limit>
          </ode>
        </physics>
      </joint>
      <link name='wrist_ft_sensor_frame'>
        <pose frame=''>0.146 0.078 0.7585 -3.14159 -0 0</pose>
        <inertial>
          <pose frame=''>0.000193 0.001251 -0.018623 0 -0 0</pose>
          <mass>0.941692</mass>
          <inertia>
            <ixx>0.0192819</ixx>
            <ixy>1.63273e-05</ixy>
            <ixz>4.64339e-05</ixz>
            <iyy>0.0192817</iyy>
            <iyz>1.0165e-05</iyz>
            <izz>0.0184914</izz>
          </inertia>
        </inertial>
        <collision name='wrist_ft_sensor_frame_fixed_joint_lump__wrist_roll_link_collision'>
          <pose frame=''>0 0 0.0735 3.14159 -0 0</pose>
          <geometry>
            <mesh>
              <scale>1 1 1</scale>
              <uri>/opt/ros/kinetic/share/hsrb_description/meshes/wrist_v0/wrist_roll.stl</uri>
            </mesh>
          </geometry>
          <surface>
            <contact>
              <ode/>
            </contact>
            <friction>
              <ode>
                <mu>0.9</mu>
                <mu2>0.9</mu2>
              </ode>
              <torsional>
                <ode/>
              </torsional>
            </friction>
            <bounce/>
          </surface>
          <max_contacts>10</max_contacts>
        </collision>
        <collision name='wrist_ft_sensor_frame_fixed_joint_lump__hand_palm_link_collision_1'>
          <pose frame=''>0.012 -0 -0.067 -3.14159 -0 3.14159</pose>
          <geometry>
            <mesh>
              <scale>1 1 1</scale>
              <uri>/opt/ros/kinetic/share/hsrb_description/meshes/hand_v0/palm.stl</uri>
            </mesh>
          </geometry>
          <surface>
            <contact>
              <ode/>
            </contact>
            <friction>
              <ode>
                <mu>0.9</mu>
                <mu2>0.9</mu2>
              </ode>
              <torsional>
                <ode/>
              </torsional>
            </friction>
            <bounce/>
          </surface>
          <max_contacts>10</max_contacts>
        </collision>
        <visual name='wrist_ft_sensor_frame_fixed_joint_lump__wrist_roll_link_visual'>
          <pose frame=''>0 0 0.0735 3.14159 -0 0</pose>
          <geometry>
            <mesh>
              <scale>1 1 1</scale>
              <uri>/opt/ros/kinetic/share/hsrb_description/meshes/wrist_v0/wrist_roll.dae</uri>
            </mesh>
          </geometry>
          <material>
            <script>
              <uri>__default__</uri>
              <name>__default__</name>
            </script>
          </material>
        </visual>
        <visual name='wrist_ft_sensor_frame_fixed_joint_lump__hand_palm_link_visual_1'>
          <pose frame=''>0.012 -0 -0.067 -3.14159 -0 3.14159</pose>
          <geometry>
            <mesh>
              <scale>1 1 1</scale>
              <uri>/opt/ros/kinetic/share/hsrb_description/meshes/hand_v0/palm_light.dae</uri>
            </mesh>
          </geometry>
          <material>
            <script>
              <uri>__default__</uri>
              <name>__default__</name>
            </script>
          </material>
        </visual>
        <velocity_decay/>
        <velocity_decay/>
        <gravity>1</gravity>
        <velocity_decay/>
        <gravity>1</gravity>
        <gravity>1</gravity>
        <velocity_decay/>
        <self_collide>0</self_collide>
        <gravity>0</gravity>
        <gravity>1</gravity>
        <velocity_decay/>
        <sensor name='hand_camera' type='camera'>
          <update_rate>10</update_rate>
          <camera name='hand_camera'>
            <horizontal_fov>2</horizontal_fov>
            <image>
              <width>640</width>
              <height>480</height>
              <format>R8G8B8</format>
            </image>
            <clip>
              <near>0.01</near>
              <far>100</far>
            </clip>
            <noise>
              <type>gaussian</type>
              <mean>0</mean>
              <stddev>0.007</stddev>
            </noise>
          </camera>
          <plugin name='camera_controller' filename='libhsrb_gazebo_ros_camera.so'>
            <robotNamespace>hsrb</robotNamespace>
            <alwaysOn>0</alwaysOn>
            <updateRate>0.0</updateRate>
            <cameraName>hand_camera</cameraName>
            <imageTopicName>image_raw</imageTopicName>
            <cameraInfoTopicName>camera_info</cameraInfoTopicName>
            <frameName>hand_camera_frame</frameName>
            <hackBaseline>0.07</hackBaseline>
            <distortionK1>0.0</distortionK1>
            <distortionK2>0.0</distortionK2>
            <distortionK3>0.0</distortionK3>
            <distortionT1>0.0</distortionT1>
            <distortionT2>0.0</distortionT2>
          </plugin>
          <pose frame=''>-0.027 -0 -0.0625 1.61304 1.57079 0.042253</pose>
        </sensor>
        <kinematic>0</kinematic>
      </link>
      <joint name='wrist_ft_sensor_frame_joint' type='revolute'>
        <child>wrist_ft_sensor_frame</child>
        <parent>wrist_ft_sensor_mount_link</parent>
        <axis>
          <xyz>1 0 0</xyz>
          <limit>
            <lower>0</lower>
            <upper>0</upper>
            <effort>100</effort>
            <velocity>1.5</velocity>
          </limit>
          <dynamics>
            <spring_reference>0</spring_reference>
            <spring_stiffness>0</spring_stiffness>
          </dynamics>
          <use_parent_model_frame>1</use_parent_model_frame>
        </axis>
        <physics>
          <provide_feedback>1</provide_feedback>
          <ode>
            <provide_feedback>1</provide_feedback>
            <limit>
              <cfm>0</cfm>
              <erp>0.2</erp>
            </limit>
          </ode>
        </physics>
      </joint>
      <link name='hand_l_proximal_link'>
        <pose frame=''>0.17475 0.1025 0.808 0 -0 -3.14159</pose>
        <inertial>
          <pose frame=''>0 0 0 0 -0 0</pose>
          <mass>0.01</mass>
          <inertia>
            <ixx>0.0015</ixx>
            <ixy>0</ixy>
            <ixz>0</ixz>
            <iyy>0.0015</iyy>
            <iyz>0</iyz>
            <izz>0.0015</izz>
          </inertia>
        </inertial>
        <gravity>1</gravity>
        <velocity_decay/>
        <self_collide>0</self_collide>
        <gravity>1</gravity>
        <kinematic>0</kinematic>
      </link>
      <joint name='hand_l_proximal_joint' type='revolute'>
        <child>hand_l_proximal_link</child>
        <parent>wrist_ft_sensor_frame</parent>
        <axis>
          <xyz>-1 0 0</xyz>
          <limit>
            <lower>-0.798</lower>
            <upper>1.24</upper>
            <effort>100</effort>
            <velocity>1</velocity>
          </limit>
          <dynamics>
            <damping>0.0001</damping>
            <friction>0</friction>
            <spring_reference>0</spring_reference>
            <spring_stiffness>0</spring_stiffness>
          </dynamics>
          <use_parent_model_frame>1</use_parent_model_frame>
        </axis>
        <physics>
          <ode>
            <limit>
              <cfm>0</cfm>
              <erp>0.2</erp>
            </limit>
          </ode>
        </physics>
      </joint>
      <link name='hand_l_spring_proximal_link'>
        <pose frame=''>0.17475 0.1025 0.808 0 -0 -3.14159</pose>
        <inertial>
          <pose frame=''>0.021418 0.00248 0.022688 0 -0 0</pose>
          <mass>0.043589</mass>
          <inertia>
            <ixx>2.60339e-05</ixx>
            <ixy>-1.44078e-07</ixy>
            <ixz>-1.98241e-06</ixz>
            <iyy>2.88248e-05</iyy>
            <iyz>-1.26842e-06</iyz>
            <izz>5.13592e-06</izz>
          </inertia>
        </inertial>
        <collision name='hand_l_spring_proximal_link_collision'>
          <pose frame=''>0 0 0 0 -0 0</pose>
          <geometry>
            <mesh>
              <scale>1 1 1</scale>
              <uri>/opt/ros/kinetic/share/hsrb_description/meshes/hand_v0/l_proximal.stl</uri>
            </mesh>
          </geometry>
          <surface>
            <contact>
              <ode/>
            </contact>
            <friction>
              <ode>
                <mu>1</mu>
                <mu2>1</mu2>
              </ode>
              <torsional>
                <ode/>
              </torsional>
            </friction>
            <bounce/>
          </surface>
          <max_contacts>10</max_contacts>
        </collision>
        <visual name='hand_l_spring_proximal_link_visual'>
          <pose frame=''>0 0 0 0 -0 0</pose>
          <geometry>
            <mesh>
              <scale>1 1 1</scale>
              <uri>/opt/ros/kinetic/share/hsrb_description/meshes/hand_v0/l_proximal.dae</uri>
            </mesh>
          </geometry>
          <material>
            <script>
              <uri>__default__</uri>
              <name>__default__</name>
            </script>
          </material>
        </visual>
        <gravity>1</gravity>
        <velocity_decay/>
        <self_collide>0</self_collide>
        <gravity>1</gravity>
        <kinematic>0</kinematic>
      </link>
      <joint name='hand_l_spring_proximal_joint' type='revolute'>
        <child>hand_l_spring_proximal_link</child>
        <parent>hand_l_proximal_link</parent>
        <axis>
          <xyz>-1 0 0</xyz>
          <limit>
            <lower>0</lower>
            <upper>0.698</upper>
            <effort>10</effort>
            <velocity>1</velocity>
          </limit>
          <dynamics>
            <damping>0.0001</damping>
            <friction>0</friction>
            <spring_reference>0</spring_reference>
            <spring_stiffness>0</spring_stiffness>
          </dynamics>
          <use_parent_model_frame>1</use_parent_model_frame>
        </axis>
        <physics>
          <ode>
            <limit>
              <cfm>0</cfm>
              <erp>0.2</erp>
            </limit>
          </ode>
        </physics>
      </joint>
      <link name='hand_l_mimic_distal_link'>
        <pose frame=''>0.17475 0.1025 0.878 0 -0 -3.14159</pose>
        <inertial>
          <pose frame=''>0 0 0 0 -0 0</pose>
          <mass>0.01</mass>
          <inertia>
            <ixx>0.0015</ixx>
            <ixy>0</ixy>
            <ixz>0</ixz>
            <iyy>0.0015</iyy>
            <iyz>0</iyz>
            <izz>0.0015</izz>
          </inertia>
        </inertial>
        <gravity>1</gravity>
        <velocity_decay/>
        <self_collide>0</self_collide>
        <gravity>1</gravity>
        <kinematic>0</kinematic>
      </link>
      <joint name='hand_l_mimic_distal_joint' type='revolute'>
        <child>hand_l_mimic_distal_link</child>
        <parent>hand_l_spring_proximal_link</parent>
        <axis>
          <xyz>-1 0 0</xyz>
          <limit>
            <lower>-0.698</lower>
            <upper>-0</upper>
            <effort>100</effort>
            <velocity>1</velocity>
          </limit>
          <dynamics>
            <damping>0.0001</damping>
            <friction>0</friction>
            <spring_reference>0</spring_reference>
            <spring_stiffness>0</spring_stiffness>
          </dynamics>
          <use_parent_model_frame>1</use_parent_model_frame>
        </axis>
        <physics>
          <ode>
            <limit>
              <cfm>0</cfm>
              <erp>0.2</erp>
            </limit>
          </ode>
        </physics>
      </joint>
      <link name='hand_l_distal_link'>
        <pose frame=''>0.17475 0.1025 0.878 0 -0 -3.14159</pose>
        <inertial>
          <pose frame=''>0.010963 0.004789 0.026131 0 -0 0</pose>
          <mass>0.047731</mass>
          <inertia>
            <ixx>0.00301442</ixx>
            <ixy>-2.43794e-06</ixy>
            <ixz>1.08454e-08</ixz>
            <iyy>0.00300659</iyy>
            <iyz>-1.38829e-06</iyz>
            <izz>0.00300979</izz>
          </inertia>
        </inertial>
        <collision name='hand_l_distal_link_collision'>
          <pose frame=''>0 0 0 0 -0 0</pose>
          <geometry>
            <mesh>
              <scale>1 1 1</scale>
              <uri>/opt/ros/kinetic/share/hsrb_description/meshes/hand_v0/l_distal.stl</uri>
            </mesh>
          </geometry>
          <surface>
            <contact>
              <ode/>
            </contact>
            <friction>
              <ode>
                <mu>1</mu>
                <mu2>1</mu2>
              </ode>
              <torsional>
                <ode/>
              </torsional>
            </friction>
            <bounce/>
          </surface>
          <max_contacts>10</max_contacts>
        </collision>
        <visual name='hand_l_distal_link_visual'>
          <pose frame=''>0 0 0 0 -0 0</pose>
          <geometry>
            <mesh>
              <scale>1 1 1</scale>
              <uri>/opt/ros/kinetic/share/hsrb_description/meshes/hand_v0/l_distal.dae</uri>
            </mesh>
          </geometry>
          <material>
            <script>
              <uri>__default__</uri>
              <name>__default__</name>
            </script>
          </material>
        </visual>
        <visual name='hand_l_distal_link_fixed_joint_lump__hand_l_finger_vacuum_frame_visual_1'>
          <pose frame=''>0.00475 -0.004468 0.026149 0.785398 -0 0</pose>
          <geometry>
            <box>
              <size>0.008 0.008 0.02</size>
            </box>
          </geometry>
          <material>
            <script>
              <uri>__default__</uri>
              <name>__default__</name>
            </script>
          </material>
        </visual>
        <velocity_decay/>
        <gravity>1</gravity>
        <velocity_decay/>
        <gravity>0</gravity>
        <gravity>1</gravity>
        <velocity_decay/>
        <self_collide>0</self_collide>
        <gravity>0</gravity>
        <kinematic>0</kinematic>
      </link>
      <joint name='hand_l_distal_joint' type='revolute'>
        <child>hand_l_distal_link</child>
        <parent>hand_l_mimic_distal_link</parent>
        <axis>
          <xyz>-1 0 0</xyz>
          <limit>
            <lower>-1.24</lower>
            <upper>0.798</upper>
            <effort>100</effort>
            <velocity>1</velocity>
          </limit>
          <dynamics>
            <damping>0.0001</damping>
            <friction>0</friction>
            <spring_reference>0</spring_reference>
            <spring_stiffness>0</spring_stiffness>
          </dynamics>
          <use_parent_model_frame>1</use_parent_model_frame>
        </axis>
        <physics>
          <ode>
            <limit>
              <cfm>0</cfm>
              <erp>0.2</erp>
            </limit>
          </ode>
        </physics>
      </joint>
      <link name='hand_motor_dummy_link'>
        <pose frame=''>0.158 0.078 0.8255 0 -0 -3.14159</pose>
        <inertial>
          <pose frame=''>0 0 0 0 -0 0</pose>
          <mass>0.01</mass>
          <inertia>
            <ixx>0.0015</ixx>
            <ixy>0</ixy>
            <ixz>0</ixz>
            <iyy>0.0015</iyy>
            <iyz>0</iyz>
            <izz>0.0015</izz>
          </inertia>
        </inertial>
        <self_collide>0</self_collide>
        <kinematic>0</kinematic>
      </link>
      <joint name='hand_motor_joint' type='revolute'>
        <child>hand_motor_dummy_link</child>
        <parent>wrist_ft_sensor_frame</parent>
        <axis>
          <xyz>-1 0 0</xyz>
          <limit>
            <lower>-0.798</lower>
            <upper>1.24</upper>
            <effort>100</effort>
            <velocity>1</velocity>
          </limit>
          <dynamics>
            <damping>0.0001</damping>
            <friction>0</friction>
            <spring_reference>0</spring_reference>
            <spring_stiffness>0</spring_stiffness>
          </dynamics>
          <use_parent_model_frame>1</use_parent_model_frame>
        </axis>
        <physics>
          <ode>
            <limit>
              <cfm>0</cfm>
              <erp>0.2</erp>
            </limit>
          </ode>
        </physics>
      </joint>
      <link name='hand_r_proximal_link'>
        <pose frame=''>0.17475 0.0535 0.808 0 -0 -3.14159</pose>
        <inertial>
          <pose frame=''>0 0 0 0 -0 0</pose>
          <mass>0.01</mass>
          <inertia>
            <ixx>0.0015</ixx>
            <ixy>0</ixy>
            <ixz>0</ixz>
            <iyy>0.0015</iyy>
            <iyz>0</iyz>
            <izz>0.0015</izz>
          </inertia>
        </inertial>
        <gravity>1</gravity>
        <velocity_decay/>
        <self_collide>0</self_collide>
        <gravity>1</gravity>
        <kinematic>0</kinematic>
      </link>
      <joint name='hand_r_proximal_joint' type='revolute'>
        <child>hand_r_proximal_link</child>
        <parent>wrist_ft_sensor_frame</parent>
        <axis>
          <xyz>1 0 0</xyz>
          <limit>
            <lower>-0.798</lower>
            <upper>1.24</upper>
            <effort>100</effort>
            <velocity>1</velocity>
          </limit>
          <dynamics>
            <damping>0.0001</damping>
            <friction>0</friction>
            <spring_reference>0</spring_reference>
            <spring_stiffness>0</spring_stiffness>
          </dynamics>
          <use_parent_model_frame>1</use_parent_model_frame>
        </axis>
        <physics>
          <ode>
            <limit>
              <cfm>0</cfm>
              <erp>0.2</erp>
            </limit>
          </ode>
        </physics>
      </joint>
      <link name='hand_r_spring_proximal_link'>
        <pose frame=''>0.17475 0.0535 0.808 0 -0 -3.14159</pose>
        <inertial>
          <pose frame=''>0.013203 0.002096 0.023311 0 -0 0</pose>
          <mass>0.043956</mass>
          <inertia>
            <ixx>2.62366e-05</ixx>
            <ixy>1.631e-08</ixy>
            <ixz>1.28184e-06</ixz>
            <iyy>2.88382e-05</iyy>
            <iyz>-1.62171e-06</iyz>
            <izz>4.95715e-06</izz>
          </inertia>
        </inertial>
        <collision name='hand_r_spring_proximal_link_collision'>
          <pose frame=''>0 0 0 0 -0 0</pose>
          <geometry>
            <mesh>
              <scale>1 1 1</scale>
              <uri>/opt/ros/kinetic/share/hsrb_description/meshes/hand_v0/r_proximal.stl</uri>
            </mesh>
          </geometry>
          <surface>
            <contact>
              <ode/>
            </contact>
            <friction>
              <ode>
                <mu>1</mu>
                <mu2>1</mu2>
              </ode>
              <torsional>
                <ode/>
              </torsional>
            </friction>
            <bounce/>
          </surface>
          <max_contacts>10</max_contacts>
        </collision>
        <visual name='hand_r_spring_proximal_link_visual'>
          <pose frame=''>0 0 0 0 -0 0</pose>
          <geometry>
            <mesh>
              <scale>1 1 1</scale>
              <uri>/opt/ros/kinetic/share/hsrb_description/meshes/hand_v0/r_proximal.dae</uri>
            </mesh>
          </geometry>
          <material>
            <script>
              <uri>__default__</uri>
              <name>__default__</name>
            </script>
          </material>
        </visual>
        <gravity>1</gravity>
        <velocity_decay/>
        <self_collide>0</self_collide>
        <gravity>1</gravity>
        <kinematic>0</kinematic>
      </link>
      <joint name='hand_r_spring_proximal_joint' type='revolute'>
        <child>hand_r_spring_proximal_link</child>
        <parent>hand_r_proximal_link</parent>
        <axis>
          <xyz>1 0 0</xyz>
          <limit>
            <lower>0</lower>
            <upper>0.698</upper>
            <effort>10</effort>
            <velocity>1</velocity>
          </limit>
          <dynamics>
            <damping>0.0001</damping>
            <friction>0</friction>
            <spring_reference>0</spring_reference>
            <spring_stiffness>0</spring_stiffness>
          </dynamics>
          <use_parent_model_frame>1</use_parent_model_frame>
        </axis>
        <physics>
          <ode>
            <limit>
              <cfm>0</cfm>
              <erp>0.2</erp>
            </limit>
          </ode>
        </physics>
      </joint>
      <link name='hand_r_mimic_distal_link'>
        <pose frame=''>0.17475 0.0535 0.878 0 -0 -3.14159</pose>
        <inertial>
          <pose frame=''>0 0 0 0 -0 0</pose>
          <mass>0.01</mass>
          <inertia>
            <ixx>0.0015</ixx>
            <ixy>0</ixy>
            <ixz>0</ixz>
            <iyy>0.0015</iyy>
            <iyz>0</iyz>
            <izz>0.0015</izz>
          </inertia>
        </inertial>
        <gravity>1</gravity>
        <velocity_decay/>
        <self_collide>0</self_collide>
        <gravity>1</gravity>
        <kinematic>0</kinematic>
      </link>
      <joint name='hand_r_mimic_distal_joint' type='revolute'>
        <child>hand_r_mimic_distal_link</child>
        <parent>hand_r_spring_proximal_link</parent>
        <axis>
          <xyz>1 0 0</xyz>
          <limit>
            <lower>-0.698</lower>
            <upper>-0</upper>
            <effort>100</effort>
            <velocity>1</velocity>
          </limit>
          <dynamics>
            <damping>0.0001</damping>
            <friction>0</friction>
            <spring_reference>0</spring_reference>
            <spring_stiffness>0</spring_stiffness>
          </dynamics>
          <use_parent_model_frame>1</use_parent_model_frame>
        </axis>
        <physics>
          <ode>
            <limit>
              <cfm>0</cfm>
              <erp>0.2</erp>
            </limit>
          </ode>
        </physics>
      </joint>
      <link name='hand_r_distal_link'>
        <pose frame=''>0.17475 0.0535 0.878 0 -0 -3.14159</pose>
        <inertial>
          <pose frame=''>0.015062 -0.011661 0.024418 0 -0 0</pose>
          <mass>0.030927</mass>
          <inertia>
            <ixx>0.00150884</ixx>
            <ixy>1.24771e-07</ixy>
            <ixz>-4.51213e-07</ixz>
            <iyy>0.00150916</iyy>
            <iyz>2.75163e-06</iyz>
            <izz>0.00150357</izz>
          </inertia>
        </inertial>
        <collision name='hand_r_distal_link_collision'>
          <pose frame=''>0 0 0 0 -0 0</pose>
          <geometry>
            <mesh>
              <scale>1 1 1</scale>
              <uri>/opt/ros/kinetic/share/hsrb_description/meshes/hand_v0/r_distal.stl</uri>
            </mesh>
          </geometry>
          <surface>
            <contact>
              <ode/>
            </contact>
            <friction>
              <ode>
                <mu>1</mu>
                <mu2>1</mu2>
              </ode>
              <torsional>
                <ode/>
              </torsional>
            </friction>
            <bounce/>
          </surface>
          <max_contacts>10</max_contacts>
        </collision>
        <visual name='hand_r_distal_link_visual'>
          <pose frame=''>0 0 0 0 -0 0</pose>
          <geometry>
            <mesh>
              <scale>1 1 1</scale>
              <uri>/opt/ros/kinetic/share/hsrb_description/meshes/hand_v0/r_distal.dae</uri>
            </mesh>
          </geometry>
          <material>
            <script>
              <uri>__default__</uri>
              <name>__default__</name>
            </script>
          </material>
        </visual>
        <velocity_decay/>
        <gravity>0</gravity>
        <gravity>1</gravity>
        <velocity_decay/>
        <self_collide>0</self_collide>
        <gravity>0</gravity>
        <kinematic>0</kinematic>
      </link>
      <joint name='hand_r_distal_joint' type='revolute'>
        <child>hand_r_distal_link</child>
        <parent>hand_r_mimic_distal_link</parent>
        <axis>
          <xyz>1 0 0</xyz>
          <limit>
            <lower>-1.24</lower>
            <upper>0.798</upper>
            <effort>100</effort>
            <velocity>1</velocity>
          </limit>
          <dynamics>
            <damping>0.0001</damping>
            <friction>0</friction>
            <spring_reference>0</spring_reference>
            <spring_stiffness>0</spring_stiffness>
          </dynamics>
          <use_parent_model_frame>1</use_parent_model_frame>
        </axis>
        <physics>
          <ode>
            <limit>
              <cfm>0</cfm>
              <erp>0.2</erp>
            </limit>
          </ode>
        </physics>
      </joint>
      <link name='base_b_bumper_link'>
        <pose frame=''>0 0.0013 0 0 -0 -3.14159</pose>
        <inertial>
          <pose frame=''>0 0 0 0 -0 0</pose>
          <mass>0.06</mass>
          <inertia>
            <ixx>0.001437</ixx>
            <ixy>0</ixy>
            <ixz>0</ixz>
            <iyy>0.001437</iyy>
            <iyz>0</iyz>
            <izz>0.002875</izz>
          </inertia>
        </inertial>
        <collision name='base_b_bumper_link_collision'>
          <pose frame=''>0 0 0 0 -0 0</pose>
          <geometry>
            <mesh>
              <scale>1 1 1</scale>
              <uri>/opt/ros/kinetic/share/hsrb_description/meshes/base_v2/bumper.stl</uri>
            </mesh>
          </geometry>
          <surface>
            <contact>
              <ode/>
            </contact>
            <friction>
              <ode>
                <mu>0.9</mu>
                <mu2>0.9</mu2>
              </ode>
              <torsional>
                <ode/>
              </torsional>
            </friction>
            <bounce/>
          </surface>
          <max_contacts>10</max_contacts>
        </collision>
        <visual name='base_b_bumper_link_visual'>
          <pose frame=''>0 0 0 0 -0 0</pose>
          <geometry>
            <mesh>
              <scale>1 1 1</scale>
              <uri>/opt/ros/kinetic/share/hsrb_description/meshes/base_v2/bumper.dae</uri>
            </mesh>
          </geometry>
          <material>
            <script>
              <uri>__default__</uri>
              <name>__default__</name>
            </script>
          </material>
        </visual>
        <gravity>1</gravity>
        <velocity_decay/>
        <self_collide>0</self_collide>
        <gravity>1</gravity>
        <sensor name='base_b_bumper_contact' type='contact'>
          <always_on>1</always_on>
          <update_rate>10</update_rate>
          <contact>
            <collision>base_b_bumper_link_collision</collision>
            <topic>__default_topic__</topic>
          </contact>
          <plugin name='hsrb_gazebo_ros_bumper_controller' filename='libhsrb_gazebo_ros_bumper.so'>
            <robotNamespace>hsrb</robotNamespace>
            <bumperTopicName>base_b_bumper_sensor</bumperTopicName>
            <frameName>base_b_bumper_link</frameName>
          </plugin>
        </sensor>
        <kinematic>0</kinematic>
      </link>
      <joint name='base_b_bumper_joint' type='revolute'>
        <child>base_b_bumper_link</child>
        <parent>base_footprint</parent>
        <axis>
          <xyz>-1 0 0</xyz>
          <limit>
            <lower>0</lower>
            <upper>0</upper>
            <effort>0</effort>
            <velocity>0</velocity>
          </limit>
          <dynamics>
            <spring_reference>0</spring_reference>
            <spring_stiffness>0</spring_stiffness>
          </dynamics>
          <use_parent_model_frame>1</use_parent_model_frame>
        </axis>
      </joint>
      <link name='base_f_bumper_link'>
        <pose frame=''>0 0 0 0 -0 0</pose>
        <inertial>
          <pose frame=''>0 0 0 0 -0 0</pose>
          <mass>0.06</mass>
          <inertia>
            <ixx>0.001437</ixx>
            <ixy>0</ixy>
            <ixz>0</ixz>
            <iyy>0.001437</iyy>
            <iyz>0</iyz>
            <izz>0.002875</izz>
          </inertia>
        </inertial>
        <collision name='base_f_bumper_link_collision'>
          <pose frame=''>0 0 0 0 -0 0</pose>
          <geometry>
            <mesh>
              <scale>1 1 1</scale>
              <uri>/opt/ros/kinetic/share/hsrb_description/meshes/base_v2/bumper.stl</uri>
            </mesh>
          </geometry>
          <surface>
            <contact>
              <ode/>
            </contact>
            <friction>
              <ode>
                <mu>0.9</mu>
                <mu2>0.9</mu2>
              </ode>
              <torsional>
                <ode/>
              </torsional>
            </friction>
            <bounce/>
          </surface>
          <max_contacts>10</max_contacts>
        </collision>
        <visual name='base_f_bumper_link_visual'>
          <pose frame=''>0 0 0 0 -0 0</pose>
          <geometry>
            <mesh>
              <scale>1 1 1</scale>
              <uri>/opt/ros/kinetic/share/hsrb_description/meshes/base_v2/bumper.dae</uri>
            </mesh>
          </geometry>
          <material>
            <script>
              <uri>__default__</uri>
              <name>__default__</name>
            </script>
          </material>
        </visual>
        <gravity>1</gravity>
        <velocity_decay/>
        <self_collide>0</self_collide>
        <gravity>1</gravity>
        <sensor name='base_f_bumper_contact' type='contact'>
          <always_on>1</always_on>
          <update_rate>10</update_rate>
          <contact>
            <collision>base_f_bumper_link_collision</collision>
            <topic>__default_topic__</topic>
          </contact>
          <plugin name='hsrb_gazebo_ros_bumper_controller' filename='libhsrb_gazebo_ros_bumper.so'>
            <robotNamespace>hsrb</robotNamespace>
            <bumperTopicName>base_f_bumper_sensor</bumperTopicName>
            <frameName>base_f_bumper_link</frameName>
          </plugin>
        </sensor>
        <kinematic>0</kinematic>
      </link>
      <joint name='base_f_bumper_joint' type='revolute'>
        <child>base_f_bumper_link</child>
        <parent>base_footprint</parent>
        <axis>
          <xyz>1 0 0</xyz>
          <limit>
            <lower>0</lower>
            <upper>0</upper>
            <effort>0</effort>
            <velocity>0</velocity>
          </limit>
          <dynamics>
            <spring_reference>0</spring_reference>
            <spring_stiffness>0</spring_stiffness>
          </dynamics>
          <use_parent_model_frame>1</use_parent_model_frame>
        </axis>
      </joint>
      <link name='base_roll_link'>
        <pose frame=''>0 0 0 0 -0 0</pose>
        <inertial>
          <pose frame=''>-0.019482 0.002191 0.071013 0 -0 0</pose>
          <mass>10.2394</mass>
          <inertia>
            <ixx>0.07671</ixx>
            <ixy>-0.01005</ixy>
            <ixz>0.001749</ixz>
            <iyy>0.09057</iyy>
            <iyz>0.001549</iyz>
            <izz>0.145</izz>
          </inertia>
        </inertial>
        <gravity>1</gravity>
        <velocity_decay/>
        <self_collide>0</self_collide>
        <gravity>1</gravity>
        <kinematic>0</kinematic>
      </link>
      <joint name='base_roll_joint' type='revolute'>
        <child>base_roll_link</child>
        <parent>base_footprint</parent>
        <axis>
          <xyz>0 0 1</xyz>
          <limit>
            <lower>-1e+16</lower>
            <upper>1e+16</upper>
          </limit>
          <dynamics>
            <damping>0.7</damping>
            <friction>0</friction>
            <spring_reference>0</spring_reference>
            <spring_stiffness>0</spring_stiffness>
          </dynamics>
          <use_parent_model_frame>1</use_parent_model_frame>
        </axis>
      </joint>
      <link name='base_l_drive_wheel_link'>
        <pose frame=''>-0.11 0.133 0.04 0 -0 0</pose>
        <inertial>
          <pose frame=''>0 0 0 0 -0 0</pose>
          <mass>0.2</mass>
          <inertia>
            <ixx>0.015</ixx>
            <ixy>0</ixy>
            <ixz>0</ixz>
            <iyy>0.015</iyy>
            <iyz>0</iyz>
            <izz>0.015</izz>
          </inertia>
        </inertial>
        <collision name='base_l_drive_wheel_link_collision'>
          <pose frame=''>0 0 0 1.5708 -0 0</pose>
          <geometry>
            <cylinder>
              <length>0.03</length>
              <radius>0.04</radius>
            </cylinder>
          </geometry>
          <surface>
            <contact>
              <ode>
                <kp>1e+06</kp>
                <kd>10</kd>
                <max_vel>1</max_vel>
                <min_depth>0</min_depth>
              </ode>
            </contact>
            <friction>
              <ode>
                <mu>1</mu>
                <mu2>1</mu2>
              </ode>
              <torsional>
                <ode/>
              </torsional>
            </friction>
            <bounce/>
          </surface>
          <max_contacts>10</max_contacts>
        </collision>
        <visual name='base_l_drive_wheel_link_visual'>
          <pose frame=''>0 0 0 1.5708 -0 0</pose>
          <geometry>
            <cylinder>
              <length>0.03</length>
              <radius>0.04</radius>
            </cylinder>
          </geometry>
          <material>
            <script>
              <name>Gazebo/FlatBlack</name>
              <uri>file://media/materials/scripts/gazebo.material</uri>
            </script>
          </material>
        </visual>
        <gravity>1</gravity>
        <velocity_decay/>
        <self_collide>0</self_collide>
        <gravity>1</gravity>
        <kinematic>0</kinematic>
      </link>
      <joint name='base_l_drive_wheel_joint' type='revolute'>
        <child>base_l_drive_wheel_link</child>
        <parent>base_roll_link</parent>
        <axis>
          <xyz>0 1 0</xyz>
          <limit>
            <lower>-1e+16</lower>
            <upper>1e+16</upper>
          </limit>
          <dynamics>
            <damping>1</damping>
            <friction>0</friction>
            <spring_reference>0</spring_reference>
            <spring_stiffness>0</spring_stiffness>
          </dynamics>
          <use_parent_model_frame>1</use_parent_model_frame>
        </axis>
      </joint>
      <link name='base_l_passive_wheel_x_frame'>
        <pose frame=''>0.1495 0.055 0.03 0 -0 0</pose>
        <inertial>
          <pose frame=''>0 0 0 0 -0 0</pose>
          <mass>0.2</mass>
          <inertia>
            <ixx>0.015</ixx>
            <ixy>0</ixy>
            <ixz>0</ixz>
            <iyy>0.015</iyy>
            <iyz>0</iyz>
            <izz>0.015</izz>
          </inertia>
        </inertial>
        <self_collide>0</self_collide>
        <kinematic>0</kinematic>
      </link>
      <joint name='base_l_passive_wheel_x_frame_joint' type='revolute'>
        <child>base_l_passive_wheel_x_frame</child>
        <parent>base_roll_link</parent>
        <axis>
          <xyz>1 0 0</xyz>
          <limit>
            <lower>-1e+16</lower>
            <upper>1e+16</upper>
          </limit>
          <dynamics>
            <damping>1</damping>
            <friction>0</friction>
            <spring_reference>0</spring_reference>
            <spring_stiffness>0</spring_stiffness>
          </dynamics>
          <use_parent_model_frame>1</use_parent_model_frame>
        </axis>
      </joint>
      <link name='base_l_passive_wheel_y_frame'>
        <pose frame=''>0.1495 0.055 0.03 0 -0 0</pose>
        <inertial>
          <pose frame=''>0 0 0 0 -0 0</pose>
          <mass>0.2</mass>
          <inertia>
            <ixx>0.015</ixx>
            <ixy>0</ixy>
            <ixz>0</ixz>
            <iyy>0.015</iyy>
            <iyz>0</iyz>
            <izz>0.015</izz>
          </inertia>
        </inertial>
        <self_collide>0</self_collide>
        <kinematic>0</kinematic>
      </link>
      <joint name='base_l_passive_wheel_y_frame_joint' type='revolute'>
        <child>base_l_passive_wheel_y_frame</child>
        <parent>base_l_passive_wheel_x_frame</parent>
        <axis>
          <xyz>0 1 0</xyz>
          <limit>
            <lower>-1e+16</lower>
            <upper>1e+16</upper>
          </limit>
          <dynamics>
            <spring_reference>0</spring_reference>
            <spring_stiffness>0</spring_stiffness>
          </dynamics>
          <use_parent_model_frame>1</use_parent_model_frame>
        </axis>
      </joint>
      <link name='base_l_passive_wheel_z_link'>
        <pose frame=''>0.1495 0.055 0.03 0 -0 0</pose>
        <inertial>
          <pose frame=''>0 0 0 0 -0 0</pose>
          <mass>0.2</mass>
          <inertia>
            <ixx>0.015</ixx>
            <ixy>0</ixy>
            <ixz>0</ixz>
            <iyy>0.015</iyy>
            <iyz>0</iyz>
            <izz>0.015</izz>
          </inertia>
        </inertial>
        <collision name='base_l_passive_wheel_z_link_collision'>
          <pose frame=''>0 0 0 0 -0 0</pose>
          <geometry>
            <sphere>
              <radius>0.03</radius>
            </sphere>
          </geometry>
          <surface>
            <contact>
              <ode>
                <max_vel>1</max_vel>
              </ode>
            </contact>
            <friction>
              <ode>
                <mu>0.1</mu>
                <mu2>0.1</mu2>
              </ode>
              <torsional>
                <ode/>
              </torsional>
            </friction>
            <bounce/>
          </surface>
          <max_contacts>10</max_contacts>
        </collision>
        <visual name='base_l_passive_wheel_z_link_visual'>
          <pose frame=''>0 0 0 0 -0 0</pose>
          <geometry>
            <sphere>
              <radius>0.03</radius>
            </sphere>
          </geometry>
          <material>
            <script>
              <name>Gazebo/FlatBlack</name>
              <uri>file://media/materials/scripts/gazebo.material</uri>
            </script>
          </material>
        </visual>
        <gravity>1</gravity>
        <velocity_decay/>
        <self_collide>0</self_collide>
        <gravity>1</gravity>
        <kinematic>0</kinematic>
      </link>
      <joint name='base_l_passive_wheel_z_joint' type='revolute'>
        <child>base_l_passive_wheel_z_link</child>
        <parent>base_l_passive_wheel_y_frame</parent>
        <axis>
          <xyz>0 0 1</xyz>
          <limit>
            <lower>-1e+16</lower>
            <upper>1e+16</upper>
          </limit>
          <dynamics>
            <spring_reference>0</spring_reference>
            <spring_stiffness>0</spring_stiffness>
          </dynamics>
          <use_parent_model_frame>1</use_parent_model_frame>
        </axis>
      </joint>
      <link name='base_r_drive_wheel_link'>
        <pose frame=''>-0.11 -0.133 0.04 0 -0 0</pose>
        <inertial>
          <pose frame=''>0 0 0 0 -0 0</pose>
          <mass>0.2</mass>
          <inertia>
            <ixx>0.015</ixx>
            <ixy>0</ixy>
            <ixz>0</ixz>
            <iyy>0.015</iyy>
            <iyz>0</iyz>
            <izz>0.015</izz>
          </inertia>
        </inertial>
        <collision name='base_r_drive_wheel_link_collision'>
          <pose frame=''>0 0 0 1.5708 -0 0</pose>
          <geometry>
            <cylinder>
              <length>0.03</length>
              <radius>0.04</radius>
            </cylinder>
          </geometry>
          <surface>
            <contact>
              <ode>
                <kp>1e+06</kp>
                <kd>10</kd>
                <max_vel>1</max_vel>
                <min_depth>0</min_depth>
              </ode>
            </contact>
            <friction>
              <ode>
                <mu>1</mu>
                <mu2>1</mu2>
              </ode>
              <torsional>
                <ode/>
              </torsional>
            </friction>
            <bounce/>
          </surface>
          <max_contacts>10</max_contacts>
        </collision>
        <visual name='base_r_drive_wheel_link_visual'>
          <pose frame=''>0 0 0 1.5708 -0 0</pose>
          <geometry>
            <cylinder>
              <length>0.03</length>
              <radius>0.04</radius>
            </cylinder>
          </geometry>
          <material>
            <script>
              <name>Gazebo/FlatBlack</name>
              <uri>file://media/materials/scripts/gazebo.material</uri>
            </script>
          </material>
        </visual>
        <gravity>1</gravity>
        <velocity_decay/>
        <self_collide>0</self_collide>
        <gravity>1</gravity>
        <kinematic>0</kinematic>
      </link>
      <joint name='base_r_drive_wheel_joint' type='revolute'>
        <child>base_r_drive_wheel_link</child>
        <parent>base_roll_link</parent>
        <axis>
          <xyz>0 1 0</xyz>
          <limit>
            <lower>-1e+16</lower>
            <upper>1e+16</upper>
          </limit>
          <dynamics>
            <damping>1</damping>
            <friction>0</friction>
            <spring_reference>0</spring_reference>
            <spring_stiffness>0</spring_stiffness>
          </dynamics>
          <use_parent_model_frame>1</use_parent_model_frame>
        </axis>
      </joint>
      <link name='base_r_passive_wheel_x_frame'>
        <pose frame=''>0.1495 -0.055 0.03 0 -0 0</pose>
        <inertial>
          <pose frame=''>0 0 0 0 -0 0</pose>
          <mass>0.2</mass>
          <inertia>
            <ixx>0.015</ixx>
            <ixy>0</ixy>
            <ixz>0</ixz>
            <iyy>0.015</iyy>
            <iyz>0</iyz>
            <izz>0.015</izz>
          </inertia>
        </inertial>
        <self_collide>0</self_collide>
        <kinematic>0</kinematic>
      </link>
      <joint name='base_r_passive_wheel_x_frame_joint' type='revolute'>
        <child>base_r_passive_wheel_x_frame</child>
        <parent>base_roll_link</parent>
        <axis>
          <xyz>1 0 0</xyz>
          <limit>
            <lower>-1e+16</lower>
            <upper>1e+16</upper>
          </limit>
          <dynamics>
            <damping>1</damping>
            <friction>0</friction>
            <spring_reference>0</spring_reference>
            <spring_stiffness>0</spring_stiffness>
          </dynamics>
          <use_parent_model_frame>1</use_parent_model_frame>
        </axis>
      </joint>
      <link name='base_r_passive_wheel_y_frame'>
        <pose frame=''>0.1495 -0.055 0.03 0 -0 0</pose>
        <inertial>
          <pose frame=''>0 0 0 0 -0 0</pose>
          <mass>0.2</mass>
          <inertia>
            <ixx>0.015</ixx>
            <ixy>0</ixy>
            <ixz>0</ixz>
            <iyy>0.015</iyy>
            <iyz>0</iyz>
            <izz>0.015</izz>
          </inertia>
        </inertial>
        <self_collide>0</self_collide>
        <kinematic>0</kinematic>
      </link>
      <joint name='base_r_passive_wheel_y_frame_joint' type='revolute'>
        <child>base_r_passive_wheel_y_frame</child>
        <parent>base_r_passive_wheel_x_frame</parent>
        <axis>
          <xyz>0 1 0</xyz>
          <limit>
            <lower>-1e+16</lower>
            <upper>1e+16</upper>
          </limit>
          <dynamics>
            <spring_reference>0</spring_reference>
            <spring_stiffness>0</spring_stiffness>
          </dynamics>
          <use_parent_model_frame>1</use_parent_model_frame>
        </axis>
      </joint>
      <link name='base_r_passive_wheel_z_link'>
        <pose frame=''>0.1495 -0.055 0.03 0 -0 0</pose>
        <inertial>
          <pose frame=''>0 0 0 0 -0 0</pose>
          <mass>0.2</mass>
          <inertia>
            <ixx>0.015</ixx>
            <ixy>0</ixy>
            <ixz>0</ixz>
            <iyy>0.015</iyy>
            <iyz>0</iyz>
            <izz>0.015</izz>
          </inertia>
        </inertial>
        <collision name='base_r_passive_wheel_z_link_collision'>
          <pose frame=''>0 0 0 0 -0 0</pose>
          <geometry>
            <sphere>
              <radius>0.03</radius>
            </sphere>
          </geometry>
          <surface>
            <contact>
              <ode>
                <max_vel>1</max_vel>
              </ode>
            </contact>
            <friction>
              <ode>
                <mu>0.1</mu>
                <mu2>0.1</mu2>
              </ode>
              <torsional>
                <ode/>
              </torsional>
            </friction>
            <bounce/>
          </surface>
          <max_contacts>10</max_contacts>
        </collision>
        <visual name='base_r_passive_wheel_z_link_visual'>
          <pose frame=''>0 0 0 0 -0 0</pose>
          <geometry>
            <sphere>
              <radius>0.03</radius>
            </sphere>
          </geometry>
          <material>
            <script>
              <name>Gazebo/FlatBlack</name>
              <uri>file://media/materials/scripts/gazebo.material</uri>
            </script>
          </material>
        </visual>
        <gravity>1</gravity>
        <velocity_decay/>
        <self_collide>0</self_collide>
        <gravity>1</gravity>
        <kinematic>0</kinematic>
      </link>
      <joint name='base_r_passive_wheel_z_joint' type='revolute'>
        <child>base_r_passive_wheel_z_link</child>
        <parent>base_r_passive_wheel_y_frame</parent>
        <axis>
          <xyz>0 0 1</xyz>
          <limit>
            <lower>-1e+16</lower>
            <upper>1e+16</upper>
          </limit>
          <dynamics>
            <spring_reference>0</spring_reference>
            <spring_stiffness>0</spring_stiffness>
          </dynamics>
          <use_parent_model_frame>1</use_parent_model_frame>
        </axis>
      </joint>
      <link name='torso_lift_link'>
        <pose frame=''>0 0 0.752 0 -0 0</pose>
        <inertial>
          <pose frame=''>-0.051142 0.003454 -0.2905 0 -0 0</pose>
          <mass>3.42078</mass>
          <inertia>
            <ixx>0.1045</ixx>
            <ixy>-0.000460885</ixy>
            <ixz>0.00010113</ixz>
            <iyy>0.105</iyy>
            <iyz>0.002941</iyz>
            <izz>0.01284</izz>
          </inertia>
        </inertial>
        <collision name='torso_lift_link_collision'>
          <pose frame=''>0 0 0 0 -0 0</pose>
          <geometry>
            <mesh>
              <scale>1 1 1</scale>
              <uri>/opt/ros/kinetic/share/hsrb_description/meshes/torso_v0/torso.stl</uri>
            </mesh>
          </geometry>
          <surface>
            <contact>
              <ode/>
            </contact>
            <friction>
              <ode>
                <mu>0.9</mu>
                <mu2>0.9</mu2>
              </ode>
              <torsional>
                <ode/>
              </torsional>
            </friction>
            <bounce/>
          </surface>
          <max_contacts>10</max_contacts>
        </collision>
        <visual name='torso_lift_link_visual'>
          <pose frame=''>0 0 0 0 -0 0</pose>
          <geometry>
            <mesh>
              <scale>1 1 1</scale>
              <uri>/opt/ros/kinetic/share/hsrb_description/meshes/torso_v0/torso_light.dae</uri>
            </mesh>
          </geometry>
          <material>
            <script>
              <uri>__default__</uri>
              <name>__default__</name>
            </script>
          </material>
        </visual>
        <gravity>1</gravity>
        <velocity_decay/>
        <self_collide>0</self_collide>
        <gravity>1</gravity>
        <kinematic>0</kinematic>
      </link>
      <joint name='torso_lift_joint' type='prismatic'>
        <child>torso_lift_link</child>
        <parent>base_footprint</parent>
        <axis>
          <xyz>0 0 1</xyz>
          <limit>
            <lower>0</lower>
            <upper>0.345</upper>
            <effort>300</effort>
            <velocity>0.1</velocity>
          </limit>
          <dynamics>
            <damping>500</damping>
            <friction>0</friction>
            <spring_reference>0</spring_reference>
            <spring_stiffness>0</spring_stiffness>
          </dynamics>
          <use_parent_model_frame>1</use_parent_model_frame>
        </axis>
        <physics>
          <ode>
            <limit>
              <cfm>0</cfm>
              <erp>0.2</erp>
            </limit>
          </ode>
        </physics>
      </joint>
      <link name='head_pan_link'>
        <pose frame=''>0 0 0.752 0 -0 0</pose>
        <inertial>
          <pose frame=''>0.001724 -0.001969 -0.028886 0 -0 0</pose>
          <mass>0.571903</mass>
          <inertia>
            <ixx>0.000971142</ixx>
            <ixy>6.17949e-05</ixy>
            <ixz>-0.000113923</ixz>
            <iyy>0.000653355</iyy>
            <iyz>6.90363e-05</iyz>
            <izz>0.000765203</izz>
          </inertia>
        </inertial>
        <collision name='head_pan_link_collision'>
          <pose frame=''>0 0 0 0 -0 0</pose>
          <geometry>
            <mesh>
              <scale>1 1 1</scale>
              <uri>/opt/ros/kinetic/share/hsrb_description/meshes/head_v1/head_pan.stl</uri>
            </mesh>
          </geometry>
          <surface>
            <contact>
              <ode/>
            </contact>
            <friction>
              <ode>
                <mu>0.9</mu>
                <mu2>0.9</mu2>
              </ode>
              <torsional>
                <ode/>
              </torsional>
            </friction>
            <bounce/>
          </surface>
          <max_contacts>10</max_contacts>
        </collision>
        <visual name='head_pan_link_visual'>
          <pose frame=''>0 0 0 0 -0 0</pose>
          <geometry>
            <mesh>
              <scale>1 1 1</scale>
              <uri>/opt/ros/kinetic/share/hsrb_description/meshes/head_v1/head_pan.dae</uri>
            </mesh>
          </geometry>
          <material>
            <script>
              <uri>__default__</uri>
              <name>__default__</name>
            </script>
          </material>
        </visual>
        <gravity>1</gravity>
        <velocity_decay/>
        <self_collide>0</self_collide>
        <gravity>1</gravity>
        <kinematic>0</kinematic>
      </link>
      <joint name='head_pan_joint' type='revolute'>
        <child>head_pan_link</child>
        <parent>torso_lift_link</parent>
        <axis>
          <xyz>0 0 1</xyz>
          <limit>
            <lower>-3.84</lower>
            <upper>1.75</upper>
            <effort>100</effort>
            <velocity>1</velocity>
          </limit>
          <dynamics>
            <damping>1</damping>
            <friction>0</friction>
            <spring_reference>0</spring_reference>
            <spring_stiffness>0</spring_stiffness>
          </dynamics>
          <use_parent_model_frame>1</use_parent_model_frame>
        </axis>
        <physics>
          <ode>
            <limit>
              <cfm>0</cfm>
              <erp>0.2</erp>
            </limit>
          </ode>
        </physics>
      </joint>
      <link name='head_tilt_link'>
        <pose frame=''>0.02 0 0.752 0 -0 0</pose>
        <inertial>
          <pose frame=''>-0.05355 -0.002148 0.117073 0 -0 0</pose>
          <mass>2.2038</mass>
          <inertia>
            <ixx>0.0280002</ixx>
            <ixy>-0.00013599</ixy>
            <ixz>0.00533594</ixz>
            <iyy>0.023706</iyy>
            <iyz>4.7745e-05</iyz>
            <izz>0.0202221</izz>
          </inertia>
        </inertial>
        <collision name='head_tilt_link_collision'>
          <pose frame=''>0 0 0 0 -0 0</pose>
          <geometry>
            <mesh>
              <scale>1 1 1</scale>
              <uri>/opt/ros/kinetic/share/hsrb_description/meshes/head_v1/head.stl</uri>
            </mesh>
          </geometry>
          <surface>
            <contact>
              <ode/>
            </contact>
            <friction>
              <ode>
                <mu>0.9</mu>
                <mu2>0.9</mu2>
              </ode>
              <torsional>
                <ode/>
              </torsional>
            </friction>
            <bounce/>
          </surface>
          <max_contacts>10</max_contacts>
        </collision>
        <collision name='head_tilt_link_collision_1'>
          <pose frame=''>0 0 0 0 -0 0</pose>
          <geometry>
            <mesh>
              <scale>1 1 1</scale>
              <uri>/opt/ros/kinetic/share/hsrb_description/meshes/head_v1/tablet.stl</uri>
            </mesh>
          </geometry>
          <surface>
            <contact>
              <ode/>
            </contact>
            <friction>
              <ode>
                <mu>0.9</mu>
                <mu2>0.9</mu2>
              </ode>
              <torsional>
                <ode/>
              </torsional>
            </friction>
            <bounce/>
          </surface>
          <max_contacts>10</max_contacts>
        </collision>
        <collision name='head_tilt_link_fixed_joint_lump__head_rgbd_sensor_link_collision_2'>
          <pose frame=''>-0.079796 0.022 0.215172 -1.5708 -0 -1.5708</pose>
          <geometry>
            <mesh>
              <scale>1 1 1</scale>
              <uri>/opt/ros/kinetic/share/hsrb_parts_description/meshes/sensors/xtion.stl</uri>
            </mesh>
          </geometry>
          <surface>
            <contact>
              <ode/>
            </contact>
            <friction>
              <ode>
                <mu>0.9</mu>
                <mu2>0.9</mu2>
              </ode>
              <torsional>
                <ode/>
              </torsional>
            </friction>
            <bounce/>
          </surface>
          <max_contacts>10</max_contacts>
        </collision>
        <visual name='head_tilt_link_visual'>
          <pose frame=''>0 0 0 0 -0 0</pose>
          <geometry>
            <mesh>
              <scale>1 1 1</scale>
              <uri>/opt/ros/kinetic/share/hsrb_description/meshes/head_v1/head_upper.dae</uri>
            </mesh>
          </geometry>
          <material>
            <script>
              <uri>__default__</uri>
              <name>__default__</name>
            </script>
          </material>
        </visual>
        <visual name='head_tilt_link_visual_1'>
          <pose frame=''>0 0 0 0 -0 0</pose>
          <geometry>
            <mesh>
              <scale>1 1 1</scale>
              <uri>/opt/ros/kinetic/share/hsrb_description/meshes/head_v1/head_tilt.dae</uri>
            </mesh>
          </geometry>
          <material>
            <script>
              <uri>__default__</uri>
              <name>__default__</name>
            </script>
          </material>
        </visual>
        <visual name='head_tilt_link_visual_2'>
          <pose frame=''>0 0 0 0 -0 0</pose>
          <geometry>
            <mesh>
              <scale>1 1 1</scale>
              <uri>/opt/ros/kinetic/share/hsrb_description/meshes/head_v1/tablet_base.dae</uri>
            </mesh>
          </geometry>
          <material>
            <script>
              <uri>__default__</uri>
              <name>__default__</name>
            </script>
          </material>
        </visual>
        <visual name='head_tilt_link_fixed_joint_lump__head_l_stereo_camera_link_visual_3'>
          <pose frame=''>0.02 0.07 0.061 -1.5708 -0 -1.5708</pose>
          <geometry>
            <mesh>
              <scale>1 1 1</scale>
              <uri>/opt/ros/kinetic/share/hsrb_parts_description/meshes/sensors/head_camera.dae</uri>
            </mesh>
          </geometry>
          <material>
            <script>
              <uri>__default__</uri>
              <name>__default__</name>
            </script>
          </material>
        </visual>
        <visual name='head_tilt_link_fixed_joint_lump__head_r_stereo_camera_link_visual_4'>
          <pose frame=''>0.02 -0.07 0.061 -1.5708 -0 -1.5708</pose>
          <geometry>
            <mesh>
              <scale>1 1 1</scale>
              <uri>/opt/ros/kinetic/share/hsrb_parts_description/meshes/sensors/head_camera.dae</uri>
            </mesh>
          </geometry>
          <material>
            <script>
              <uri>__default__</uri>
              <name>__default__</name>
            </script>
          </material>
        </visual>
        <visual name='head_tilt_link_fixed_joint_lump__head_rgbd_sensor_link_visual_5'>
          <pose frame=''>-0.079796 0.022 0.215172 -1.5708 -0 -1.5708</pose>
          <geometry>
            <mesh>
              <scale>1 1 1</scale>
              <uri>/opt/ros/kinetic/share/hsrb_parts_description/meshes/sensors/xtion.dae</uri>
            </mesh>
          </geometry>
          <material>
            <script>
              <uri>__default__</uri>
              <name>__default__</name>
            </script>
          </material>
        </visual>
        <velocity_decay/>
        <velocity_decay/>
        <velocity_decay/>
        <sensor name='head_center_camera' type='camera'>
          <update_rate>10</update_rate>
          <camera name='head_center_camera'>
            <horizontal_fov>2</horizontal_fov>
            <image>
              <width>640</width>
              <height>480</height>
              <format>R8G8B8</format>
            </image>
            <clip>
              <near>0.01</near>
              <far>100</far>
            </clip>
            <noise>
              <type>gaussian</type>
              <mean>0</mean>
              <stddev>0.007</stddev>
            </noise>
          </camera>
          <plugin name='camera_controller' filename='libhsrb_gazebo_ros_camera.so'>
            <robotNamespace>hsrb</robotNamespace>
            <alwaysOn>0</alwaysOn>
            <updateRate>0.0</updateRate>
            <cameraName>head_center_camera</cameraName>
            <imageTopicName>image_raw</imageTopicName>
            <cameraInfoTopicName>camera_info</cameraInfoTopicName>
            <frameName>head_center_camera_frame</frameName>
            <hackBaseline>0.07</hackBaseline>
            <distortionK1>0.0</distortionK1>
            <distortionK2>0.0</distortionK2>
            <distortionK3>0.0</distortionK3>
            <distortionT1>0.0</distortionT1>
            <distortionT2>0.0</distortionT2>
          </plugin>
          <pose frame=''>0.0195 0 0.061 0 -0 0</pose>
        </sensor>
        <velocity_decay/>
        <velocity_decay/>
        <sensor name='head_l_stereo_camera' type='camera'>
          <update_rate>4</update_rate>
          <camera name='head_l_stereo_camera'>
            <horizontal_fov>1.16763</horizontal_fov>
            <image>
              <width>1280</width>
              <height>960</height>
              <format>R8G8B8</format>
            </image>
            <clip>
              <near>0.05</near>
              <far>100</far>
            </clip>
            <noise>
              <type>gaussian</type>
              <mean>0</mean>
              <stddev>0.007</stddev>
            </noise>
          </camera>
          <plugin name='camera_controller' filename='libhsrb_gazebo_ros_camera.so'>
            <alwaysOn>0</alwaysOn>
            <updateRate>0.0</updateRate>
            <cameraName>head_l_stereo_camera</cameraName>
            <imageTopicName>image_rect_color</imageTopicName>
            <cameraInfoTopicName>camera_info</cameraInfoTopicName>
            <frameName>head_l_stereo_camera_frame</frameName>
            <robotNamespace>hsrb</robotNamespace>
            <hackBaseline>0.0</hackBaseline>
            <distortionK1>0.0</distortionK1>
            <distortionK2>0.0</distortionK2>
            <distortionK3>0.0</distortionK3>
            <distortionT1>0.0</distortionT1>
            <distortionT2>0.0</distortionT2>
          </plugin>
          <pose frame=''>0.02 0.07 0.061 0 -0 0</pose>
        </sensor>
        <gravity>1</gravity>
        <velocity_decay/>
        <gravity>1</gravity>
        <gravity>1</gravity>
        <velocity_decay/>
        <sensor name='head_r_stereo_camera' type='camera'>
          <update_rate>4</update_rate>
          <camera name='head_r_stereo_camera'>
            <horizontal_fov>1.16763</horizontal_fov>
            <image>
              <width>1280</width>
              <height>960</height>
              <format>R8G8B8</format>
            </image>
            <clip>
              <near>0.05</near>
              <far>100</far>
            </clip>
            <noise>
              <type>gaussian</type>
              <mean>0</mean>
              <stddev>0.007</stddev>
            </noise>
          </camera>
          <plugin name='camera_controller' filename='libhsrb_gazebo_ros_camera.so'>
            <alwaysOn>0</alwaysOn>
            <updateRate>0.0</updateRate>
            <cameraName>head_r_stereo_camera</cameraName>
            <imageTopicName>image_rect_color</imageTopicName>
            <cameraInfoTopicName>camera_info</cameraInfoTopicName>
            <frameName>head_r_stereo_camera_frame</frameName>
            <robotNamespace>hsrb</robotNamespace>
            <hackBaseline>0.14</hackBaseline>
            <distortionK1>0.0</distortionK1>
            <distortionK2>0.0</distortionK2>
            <distortionK3>0.0</distortionK3>
            <distortionT1>0.0</distortionT1>
            <distortionT2>0.0</distortionT2>
          </plugin>
          <pose frame=''>0.02 -0.07 0.061 0 -0 0</pose>
        </sensor>
        <gravity>1</gravity>
        <velocity_decay/>
        <self_collide>0</self_collide>
        <gravity>1</gravity>
        <gravity>1</gravity>
        <velocity_decay/>
        <sensor name='openni_camera_camera' type='depth'>
          <always_on>0</always_on>
          <update_rate>30</update_rate>
          <visualize>1</visualize>
          <camera name='__default__'>
            <horizontal_fov>1.047</horizontal_fov>
            <image>
              <width>640</width>
              <height>480</height>
              <format>B8G8R8</format>
            </image>
            <depth_camera>
              <output>depths</output>
            </depth_camera>
            <clip>
              <near>0.1</near>
              <far>100</far>
            </clip>
          </camera>
          <plugin name='head_rgbd_sensor_controller' filename='libhsrb_gazebo_ros_openni_kinect.so'>
            <alwaysOn>true</alwaysOn>
            <baseline>0.2</baseline>
            <updateRate>1.0</updateRate>
            <cameraName>head_rgbd_sensor</cameraName>
            <frameName>head_rgbd_sensor_rgb_frame</frameName>
            <imageTopicName>/hsrb/head_rgbd_sensor/rgb/image_rect_color</imageTopicName>
            <cameraInfoTopicName>/hsrb/head_rgbd_sensor/rgb/camera_info</cameraInfoTopicName>
            <depthImageTopicName>/hsrb/head_rgbd_sensor/depth_registered/image_rect_raw</depthImageTopicName>
            <pointCloudTopicName>/hsrb/head_rgbd_sensor/depth_registered/rectified_points</pointCloudTopicName>
            <depthImageCameraInfoTopicName>/hsrb/head_rgbd_sensor/depth_registered/camera_info</depthImageCameraInfoTopicName>
            <pointCloudCutoff>0.5</pointCloudCutoff>
            <pointCloudCutoffMax>9.2</pointCloudCutoffMax>
            <distortionK1>0.0</distortionK1>
            <distortionK2>0.0</distortionK2>
            <distortionK3>0.0</distortionK3>
            <distortionT1>0.0</distortionT1>
            <distortionT2>0.0</distortionT2>
            <CxPrime>0.0</CxPrime>
            <Cx>0.0</Cx>
            <Cy>0.0</Cy>
            <focalLength>0.0</focalLength>
            <hackBaseline>0</hackBaseline>
            <encoding>16UC1</encoding>
            <robotNamespace>/</robotNamespace>
          </plugin>
          <pose frame=''>-0.079796 0.022 0.215172 0 -0 0</pose>
        </sensor>
        <kinematic>0</kinematic>
      </link>
      <joint name='head_tilt_joint' type='revolute'>
        <child>head_tilt_link</child>
        <parent>head_pan_link</parent>
        <axis>
          <xyz>0 -1 0</xyz>
          <limit>
            <lower>-1.57</lower>
            <upper>0.52</upper>
            <effort>100</effort>
            <velocity>1</velocity>
          </limit>
          <dynamics>
            <damping>10</damping>
            <friction>0</friction>
            <spring_reference>0</spring_reference>
            <spring_stiffness>0</spring_stiffness>
          </dynamics>
          <use_parent_model_frame>1</use_parent_model_frame>
        </axis>
        <physics>
          <ode>
            <limit>
              <cfm>0</cfm>
              <erp>0.2</erp>
            </limit>
          </ode>
        </physics>
      </joint>
      <plugin name='torso_mimic_plugin' filename='libtmc_gazebo_mimic_plugin.so'>
        <joint>torso_lift_joint</joint>
        <mimicJoint>arm_lift_joint</mimicJoint>
        <multiplier>0.5</multiplier>
        <robotNamespace>/</robotNamespace>
      </plugin>
      <plugin name='ft_sensor' filename='libgazebo_ros_ft_sensor.so'>
        <updateRate>30.0</updateRate>
        <topicName>wrist_wrench/raw</topicName>
        <jointName>wrist_ft_sensor_frame_joint</jointName>
        <robotNamespace>hsrb</robotNamespace>
      </plugin>
      <plugin name='hsrb_hrh_gripper_plugin' filename='libtmc_gazebo_hrh_gripper.so'>
        <sensitiveness>0.05</sensitiveness>
        <update_rate>1000.0</update_rate>
        <max_torque>8.0</max_torque>
        <error_tolerance>0.0872</error_tolerance>
        <stall_timeout>2.0</stall_timeout>
        <robotNamespace>/</robotNamespace>
      </plugin>
      <plugin name='hsrb_grasp_hack_plugin' filename='libhsrb_grasp_hack.so'>
        <grasp_check>
          <attach_steps>1</attach_steps>
          <detach_steps>2</detach_steps>
          <min_contact_count>1</min_contact_count>
          <max_attach_weight>1.2</max_attach_weight>
        </grasp_check>
        <gripper_link>hand_r_distal_link</gripper_link>
        <gripper_link>hand_l_distal_link</gripper_link>
        <gripper_link>hand_r_spring_proximal_link</gripper_link>
        <gripper_link>hand_l_spring_proximal_link</gripper_link>
        <palm_link>wrist_ft_sensor_frame</palm_link>
        <robotNamespace>/</robotNamespace>
      </plugin>
      <static>0</static>
      <plugin name='hsrb_ros_control' filename='libhsrb_gazebo_ros_control.so'>
        <robotNamespace>hsrb</robotNamespace>
        <legacyModeNS>true</legacyModeNS>
      </plugin>
      <plugin name='hsrb_p3d_ground_truth' filename='libgazebo_ros_p3d.so'>
        <robotNamespace>hsrb</robotNamespace>
        <bodyName>base_footprint</bodyName>
        <topicName>odom_ground_truth</topicName>
        <frameName>map</frameName>
        <updateRate>30</updateRate>
      </plugin>
      <pose frame=''>0 0 0 0 -0 0</pose>
    </model>
    <model name='trash_lid_hole_2'>
      <link name='link_0'>
        <pose frame=''>-0.007084 0.00178 0.249083 0 -0 0</pose>
        <inertial>
          <mass>1</mass>
          <inertia>
            <ixx>0.166667</ixx>
            <ixy>0</ixy>
            <ixz>0</ixz>
            <iyy>0.166667</iyy>
            <iyz>0</iyz>
            <izz>0.166667</izz>
          </inertia>
          <pose frame=''>0 0 0 0 -0 0</pose>
        </inertial>
        <self_collide>0</self_collide>
        <kinematic>0</kinematic>
        <gravity>1</gravity>
        <visual name='visual'>
          <pose frame=''>0 0 0 0 -0 0</pose>
          <geometry>
            <mesh>
              <uri>/home/takeshi/.gazebo/models/trash_lid_hole_2/meshes/hole_lid.dae</uri>
              <scale>1 1 1</scale>
            </mesh>
          </geometry>
          <material>
            <lighting>1</lighting>
            <script>
              <uri>file://media/materials/scripts/gazebo.material</uri>
              <name>Gazebo/Grey</name>
            </script>
            <shader type='pixel'>
              <normal_map>__default__</normal_map>
            </shader>
            <ambient>1 1 1 1</ambient>
            <diffuse>0.7 0.7 0.7 1</diffuse>
            <specular>0.01 0.01 0.01 1</specular>
            <emissive>0 0 0 1</emissive>
          </material>
          <transparency>0</transparency>
          <cast_shadows>1</cast_shadows>
        </visual>
        <collision name='collision'>
          <laser_retro>0</laser_retro>
          <max_contacts>10</max_contacts>
          <pose frame=''>0 0 0 0 -0 0</pose>
          <geometry>
            <mesh>
              <uri>/home/takeshi/.gazebo/models/trash_lid_hole_2/meshes/hole_lid.dae</uri>
              <scale>1 1 1</scale>
            </mesh>
          </geometry>
          <surface>
            <friction>
              <ode>
                <mu>1</mu>
                <mu2>1</mu2>
                <fdir1>0 0 0</fdir1>
                <slip1>0</slip1>
                <slip2>0</slip2>
              </ode>
              <torsional>
                <coefficient>1</coefficient>
                <patch_radius>0</patch_radius>
                <surface_radius>0</surface_radius>
                <use_patch_radius>1</use_patch_radius>
                <ode>
                  <slip>0</slip>
                </ode>
              </torsional>
            </friction>
            <bounce>
              <restitution_coefficient>0</restitution_coefficient>
              <threshold>1e+06</threshold>
            </bounce>
            <contact>
              <collide_without_contact>0</collide_without_contact>
              <collide_without_contact_bitmask>1</collide_without_contact_bitmask>
              <collide_bitmask>1</collide_bitmask>
              <ode>
                <soft_cfm>0</soft_cfm>
                <soft_erp>0.2</soft_erp>
                <kp>1e+13</kp>
                <kd>1</kd>
                <max_vel>0.01</max_vel>
                <min_depth>0</min_depth>
              </ode>
              <bullet>
                <split_impulse>1</split_impulse>
                <split_impulse_penetration_threshold>-0.01</split_impulse_penetration_threshold>
                <soft_cfm>0</soft_cfm>
                <soft_erp>0.2</soft_erp>
                <kp>1e+13</kp>
                <kd>1</kd>
              </bullet>
            </contact>
          </surface>
        </collision>
      </link>
      <link name='link_1'>
        <pose frame=''>0.007075 -0.00178 -0.249083 0 -0 0</pose>
        <inertial>
          <mass>1</mass>
          <inertia>
            <ixx>0.166667</ixx>
            <ixy>0</ixy>
            <ixz>0</ixz>
            <iyy>0.166667</iyy>
            <iyz>0</iyz>
            <izz>0.166667</izz>
          </inertia>
        </inertial>
        <self_collide>0</self_collide>
        <kinematic>0</kinematic>
        <visual name='visual'>
          <pose frame=''>0 0 0 0 -0 0</pose>
          <geometry>
            <mesh>
              <uri>/home/takeshi/.gazebo/models/trash_lid_hole_2/meshes/trash_bin.dae</uri>
              <scale>1 1 1</scale>
            </mesh>
          </geometry>
          <material>
            <lighting>1</lighting>
            <script>
              <uri>file://media/materials/scripts/gazebo.material</uri>
              <name>Gazebo/Grey</name>
            </script>
            <shader type='pixel'/>
            <ambient>0.3 0.3 0.3 1</ambient>
            <diffuse>0.7 0.7 0.7 1</diffuse>
            <specular>0.01 0.01 0.01 1</specular>
            <emissive>0 0 0 1</emissive>
          </material>
          <transparency>0</transparency>
          <cast_shadows>1</cast_shadows>
        </visual>
        <collision name='collision'>
          <laser_retro>0</laser_retro>
          <max_contacts>10</max_contacts>
          <pose frame=''>0 0 0 0 -0 0</pose>
          <geometry>
            <mesh>
              <uri>/home/takeshi/.gazebo/models/trash_lid_hole_2/meshes/trash_bin.dae</uri>
              <scale>1 1 1</scale>
            </mesh>
          </geometry>
          <surface>
            <friction>
              <ode>
                <mu>1</mu>
                <mu2>1</mu2>
                <fdir1>0 0 0</fdir1>
                <slip1>0</slip1>
                <slip2>0</slip2>
              </ode>
              <torsional>
                <coefficient>1</coefficient>
                <patch_radius>0</patch_radius>
                <surface_radius>0</surface_radius>
                <use_patch_radius>1</use_patch_radius>
                <ode>
                  <slip>0</slip>
                </ode>
              </torsional>
            </friction>
            <bounce>
              <restitution_coefficient>0</restitution_coefficient>
              <threshold>1e+06</threshold>
            </bounce>
            <contact>
              <collide_without_contact>0</collide_without_contact>
              <collide_without_contact_bitmask>1</collide_without_contact_bitmask>
              <collide_bitmask>1</collide_bitmask>
              <ode>
                <soft_cfm>0</soft_cfm>
                <soft_erp>0.2</soft_erp>
                <kp>1e+13</kp>
                <kd>1</kd>
                <max_vel>0.01</max_vel>
                <min_depth>0</min_depth>
              </ode>
              <bullet>
                <split_impulse>1</split_impulse>
                <split_impulse_penetration_threshold>-0.01</split_impulse_penetration_threshold>
                <soft_cfm>0</soft_cfm>
                <soft_erp>0.2</soft_erp>
                <kp>1e+13</kp>
                <kd>1</kd>
              </bullet>
            </contact>
          </surface>
        </collision>
      </link>
      <joint name='link_1_JOINT_0' type='fixed'>
        <parent>link_1</parent>
        <child>link_0</child>
        <pose frame=''>0 0 0 0 -0 0</pose>
        <physics>
          <ode>
            <limit>
              <cfm>0</cfm>
              <erp>0.2</erp>
            </limit>
            <suspension>
              <cfm>0</cfm>
              <erp>0.2</erp>
            </suspension>
          </ode>
        </physics>
      </joint>
      <static>0</static>
      <allow_auto_disable>1</allow_auto_disable>
      <pose frame=''>1.74666 -0.092627 0 0 -0 0</pose>
    </model>
    <state world_name='default'>
      <sim_time>60 337000000</sim_time>
      <real_time>246 838960790</real_time>
      <wall_time>1581024746 275927360</wall_time>
      <iterations>60337</iterations>
      <model name='ground_plane'>
        <pose frame=''>0 0 0 0 -0 0</pose>
        <scale>1 1 1</scale>
        <link name='link'>
          <pose frame=''>0 0 0 0 -0 0</pose>
          <velocity>0 0 0 0 -0 0</velocity>
          <acceleration>0 0 0 0 -0 0</acceleration>
          <wrench>0 0 0 0 -0 0</wrench>
        </link>
      </model>
      <model name='hsrb'>
        <pose frame=''>-0.000524 -0.001518 -0.000106 1.7e-05 -3.6e-05 -0.01386</pose>
        <scale>1 1 1</scale>
        <link name='arm_flex_link'>
          <pose frame=''>0.14153 0.074514 0.389897 1.9e-05 3e-05 -0.013862</pose>
          <velocity>-0.005386 0.002243 0.000772 0.000666 0.020915 0.012394</velocity>
          <acceleration>-5.69814 3.23926 1.50613 2.61211 -0.721493 -2.02726</acceleration>
          <wrench>-7.63146 4.33831 2.01714 0 -0 0</wrench>
        </link>
        <link name='arm_lift_link'>
          <pose frame=''>-0.000538 -0.001524 0.389892 2.1e-05 -2.8e-05 -0.013862</pose>
          <velocity>-0.004438 0.000427 -0.002852 0.000389 -0.02571 0.01247</velocity>
          <acceleration>-6.53959 1.40235 -3.09398 -1.11666 1.3896 0.388348</acceleration>
          <wrench>-8.34334 1.78915 -3.94737 0 -0 0</wrench>
        </link>
        <link name='arm_roll_link'>
          <pose frame=''>0.146539 0.074438 0.734896 -2.9e-05 1.8e-05 -1.58387</pose>
          <velocity>0.001836 0.001933 0.000602 0.002568 0.02066 0.003015</velocity>
          <acceleration>1.38062 3.13845 1.12937 0.858234 1.38085 0.730596</acceleration>
          <wrench>0.342307 0.778135 0.280013 0 -0 0</wrench>
        </link>
        <link name='base_b_bumper_link'>
          <pose frame=''>-0.000506 -0.000218 -0.000106 -1.7e-05 3.7e-05 3.12773</pose>
          <velocity>0.006022 0.000154 0.002545 -0.001168 -0.027289 0.012856</velocity>
          <acceleration>12.2615 -0.244274 4.95909 -2.23854 1.11571 -3.01145</acceleration>
          <wrench>0.735691 -0.014656 0.297546 0 -0 0</wrench>
        </link>
        <link name='base_f_bumper_link'>
          <pose frame=''>-0.000524 -0.001518 -0.000106 1.7e-05 -3.7e-05 -0.01386</pose>
          <velocity>0.00604 0.000154 0.002546 -0.001173 -0.027295 0.012855</velocity>
          <acceleration>12.2928 -0.244755 4.96107 -2.2476 1.10325 -3.01278</acceleration>
          <wrench>0.737568 -0.014685 0.297664 0 -0 0</wrench>
        </link>
        <link name='base_footprint'>
          <pose frame=''>-0.000524 -0.001518 -0.000106 1.7e-05 -3.6e-05 -0.01386</pose>
          <velocity>0.005997 0.000158 0.002524 -0.000976 -0.027071 0.012788</velocity>
          <acceleration>2.62015 -0.486597 3.49575 -1.87691 1.54083 2.98291</acceleration>
          <wrench>131.06 -24.3396 174.858 0 -0 0</wrench>
        </link>
        <link name='base_l_drive_wheel_link'>
          <pose frame=''>-0.108674 0.132994 0.039888 1e-05 0.033809 -0.013876</pose>
          <velocity>0.011207 -5.6e-05 -0.001374 0.001398 0.280554 -0.005038</velocity>
          <acceleration>23.01 -0.128292 -2.94863 0.087611 -1.40936 1.75178</acceleration>
          <wrench>4.602 -0.025658 -0.589726 0 -0 0</wrench>
        </link>
        <link name='base_l_passive_wheel_x_frame'>
          <pose frame=''>0.149717 0.051402 0.029947 -0.052749 -6.6e-05 -0.013877</pose>
          <velocity>0.004185 -0.000485 0.015772 -0.0001 -0.033448 -0.004875</velocity>
          <acceleration>8.73749 -2.1102 31.5327 2.28907 1.42589 -1.06876</acceleration>
          <wrench>1.7475 -0.422039 6.30654 0 -0 0</wrench>
        </link>
        <link name='base_l_passive_wheel_y_frame'>
          <pose frame=''>0.149715 0.051402 0.029976 -3.04334 -1.00334 3.04478</pose>
          <velocity>0.003833 -0.000458 0.021586 0.001337 0.070021 -0.010336</velocity>
          <acceleration>8.01209 -2.05436 43.1494 -3.06376 -0.765471 1.68501</acceleration>
          <wrench>1.60242 -0.410872 8.62988 0 -0 0</wrench>
        </link>
        <link name='base_l_passive_wheel_z_link'>
          <pose frame=''>0.149706 0.051403 0.030004 2.26357 -0.578093 -1.97704</pose>
          <velocity>0.002178 -0.000326 0.027373 0.010751 0.07094 -0.004408</velocity>
          <acceleration>4.60933 -1.7913 54.7127 2.9371 0.987126 3.11314</acceleration>
          <wrench>0.921866 -0.35826 10.9425 0 -0 0</wrench>
        </link>
        <link name='base_r_drive_wheel_link'>
          <pose frame=''>-0.112367 -0.13298 0.039887 6e-06 -0.058473 -0.013878</pose>
          <velocity>0.008482 1e-05 -0.00053 -0.000237 0.212399 -0.004601</velocity>
          <acceleration>16.7636 0.014031 -1.3003 -0.330763 -0.886153 -0.511515</acceleration>
          <wrench>3.35273 0.002806 -0.260059 0 -0 0</wrench>
        </link>
        <link name='base_r_passive_wheel_x_frame'>
          <pose frame=''>0.14819 -0.058587 0.029944 -0.02362 -4.7e-05 -0.013877</pose>
          <velocity>0.003427 -0.000502 0.015574 -0.010126 -0.029341 -0.00563</velocity>
          <acceleration>6.78854 -2.17326 31.13 2.31148 0.11206 0.554204</acceleration>
          <wrench>1.35771 -0.434653 6.226 0 -0 0</wrench>
        </link>
        <link name='base_r_passive_wheel_y_frame'>
          <pose frame=''>0.148189 -0.058587 0.029974 -3.11738 -0.221544 3.12239</pose>
          <velocity>0.003119 -0.00047 0.021713 -0.008983 0.05205 -0.007536</velocity>
          <acceleration>6.1484 -2.13381 43.4018 3.12074 -0.337258 -0.758726</acceleration>
          <wrench>1.22968 -0.426762 8.68036 0 -0 0</wrench>
        </link>
        <link name='base_r_passive_wheel_z_link'>
          <pose frame=''>0.148181 -0.058586 0.030005 3.01796 -0.185884 -2.4591</pose>
          <velocity>0.001678 -0.000321 0.027824 0.01062 0.05447 0.07907</velocity>
          <acceleration>3.15758 -1.94609 55.6179 -2.5618 -1.13358 -0.227848</acceleration>
          <wrench>0.631517 -0.389218 11.1236 0 -0 0</wrench>
        </link>
        <link name='base_roll_link'>
          <pose frame=''>-0.000526 -0.001518 -0.000104 1.1e-05 -6.6e-05 -0.013876</pose>
          <velocity>0.005771 0.000139 0.002821 -0.002543 -0.033627 -0.005473</velocity>
          <acceleration>6.95365 0.367628 4.17325 0.960486 0.450784 -2.23116</acceleration>
          <wrench>71.2012 3.76429 42.7316 0 -0 0</wrench>
        </link>
        <link name='hand_l_distal_link'>
          <pose frame=''>0.172493 -0.118788 0.706027 3.09631 -1.57028 -1.50001</pose>
          <velocity>-7.6e-05 0.000539 2.6e-05 3.6e-05 -7.2e-05 6.7e-05</velocity>
          <acceleration>-0.074837 0.537967 0.024292 0.036321 -0.072083 0.066536</acceleration>
          <wrench>-0.003572 0.025678 0.00116 0 -0 0</wrench>
        </link>
        <link name='hand_l_mimic_distal_link'>
          <pose frame=''>0.172493 -0.118788 0.706026 3.11463 -1.57028 -1.50001</pose>
          <velocity>-7.3e-05 0.000513 1.9e-05 4e-05 -7.1e-05 0</velocity>
          <acceleration>-0.072797 0.513024 0.019385 0.039858 -0.071288 2.7e-05</acceleration>
          <wrench>-0.000728 0.00513 0.000194 0 -0 0</wrench>
        </link>
        <link name='hand_l_proximal_link'>
          <pose frame=''>0.169427 -0.048855 0.706064 3.11092 -1.57027 -1.524</pose>
          <velocity>0.000707 0.00062 4.3e-05 0.000482 -0.000721 0.128457</velocity>
          <acceleration>1.02974 0.058843 0.108132 0.683327 -1.44098 -0.017855</acceleration>
          <wrench>0.010297 0.000588 0.001081 0 -0 0</wrench>
        </link>
        <link name='hand_l_spring_proximal_link'>
          <pose frame=''>0.169427 -0.048855 0.706064 3.11529 -1.57028 -1.50068</pose>
          <velocity>0.0007 0.000625 1e-05 0.000161 0.000303 -0.011913</velocity>
          <acceleration>0.571565 0.088524 0.027664 0.955319 1.01384 -1.15977</acceleration>
          <wrench>0.024914 0.003859 0.001206 0 -0 0</wrench>
        </link>
        <link name='hand_motor_dummy_link'>
          <pose frame=''>0.144701 -0.066042 0.722807 3.11086 -1.57027 -1.52407</pose>
          <velocity>0.000719 0.000777 6.4e-05 0.00045 -0.000653 0</velocity>
          <acceleration>0.718526 0.776501 0.064236 0.450289 -0.653303 6.4e-05</acceleration>
          <wrench>0.007185 0.007765 0.000642 0 -0 0</wrench>
        </link>
        <link name='hand_r_distal_link'>
          <pose frame=''>0.114505 -0.117962 0.70603 3.05723 -1.57031 -1.54168</pose>
          <velocity>-0.000227 0.000708 -9e-06 -1.7e-05 -2.5e-05 -3.2e-05</velocity>
          <acceleration>-0.228515 0.707919 -0.008374 -0.017347 -0.025279 -0.032093</acceleration>
          <wrench>-0.007067 0.021894 -0.000259 0 -0 0</wrench>
        </link>
        <link name='hand_r_mimic_distal_link'>
          <pose frame=''>0.114505 -0.117962 0.70603 3.02784 -1.57031 -1.54173</pose>
          <velocity>-0.000238 0.000684 -1.3e-05 -1.6e-05 -2.6e-05 -1e-06</velocity>
          <acceleration>-0.237535 0.683514 -0.013151 -0.015785 -0.02563 -0.000677</acceleration>
          <wrench>-0.002375 0.006835 -0.000132 0 -0 0</wrench>
        </link>
        <link name='hand_r_proximal_link'>
          <pose frame=''>0.120431 -0.048214 0.706066 3.03677 -1.57028 -1.52441</pose>
          <velocity>0.00065 0.000631 1.9e-05 0.000468 -0.000659 0.001261</velocity>
          <acceleration>1.01504 0.367385 0.049652 0.658481 -1.42245 -0.000344</acceleration>
          <wrench>0.01015 0.003674 0.000497 0 -0 0</wrench>
        </link>
        <link name='hand_r_spring_proximal_link'>
          <pose frame=''>0.120431 -0.048214 0.706066 3.13997 -1.57032 -1.65393</pose>
          <velocity>0.000622 0.000665 -4e-06 -1.3e-05 0.000214 -0.011346</velocity>
          <acceleration>0.934999 0.444298 0.011581 -3.09467 0.261059 3.04732</acceleration>
          <wrench>0.041099 0.01953 0.000509 0 -0 0</wrench>
        </link>
        <link name='head_pan_link'>
          <pose frame=''>-0.000547 -0.00153 0.765452 1.4e-05 -1.6e-05 -0.013866</pose>
          <velocity>-0.013167 0.000997 -0.000913 -0.002194 -0.021875 0.002167</velocity>
          <acceleration>-25.4958 1.2241 -1.75011 0.64024 0.572053 1.06954</acceleration>
          <wrench>-14.5811 0.700065 -1.00089 0 -0 0</wrench>
        </link>
        <link name='head_tilt_link'>
          <pose frame=''>0.019456 -0.001808 0.76545 1.5e-05 -0.000932 -0.013879</pose>
          <velocity>-0.012023 0.00098 -0.00106 0.001637 0.070123 -0.000547</velocity>
          <acceleration>-8.01305 1.16305 5.45141 0.266317 0.438817 2.86071</acceleration>
          <wrench>-17.6592 2.56313 12.0138 0 -0 0</wrench>
        </link>
        <link name='torso_lift_link'>
          <pose frame=''>-0.000549 -0.001531 0.765452 1.7e-05 -2.8e-05 -0.013864</pose>
          <velocity>-0.013633 0.00085 -0.000874 -0.000945 -0.025034 0.012029</velocity>
          <acceleration>-13.0027 -0.502716 -4.36592 -1.77035 -0.659508 1.61655</acceleration>
          <wrench>-44.4793 -1.71968 -14.9348 0 -0 0</wrench>
        </link>
        <link name='wrist_flex_link'>
          <pose frame=''>0.14654 0.074439 0.734896 -3.05151 1.57028 1.64782</pose>
          <velocity>0.00184 0.001961 0.000607 0.000411 0.021429 0.00045</velocity>
          <acceleration>4.10841 2.90582 1.36911 -0.978222 -0.678384 1.69012</acceleration>
          <wrench>2.79875 1.97951 0.93267 0 -0 0</wrench>
        </link>
        <link name='wrist_ft_sensor_frame'>
          <pose frame=''>0.145577 0.000946 0.734842 0.064998 1.57028 1.62272</pose>
          <velocity>0.000736 0.000764 9.2e-05 0.000441 -0.000652 -0.000444</velocity>
          <acceleration>1.3397 0.505811 0.173065 0.590852 -1.48635 -0.144752</acceleration>
          <wrench>1.26158 0.476319 0.162974 0 -0 0</wrench>
        </link>
        <link name='wrist_ft_sensor_mount_link'>
          <pose frame=''>0.146537 0.074441 0.734875 -3.07605 1.57028 1.62327</pose>
          <velocity>0.000264 0.000239 -5.1e-05 0.000297 -0.000652 0.000784</velocity>
          <acceleration>0.955143 -0.561173 -0.121326 0.316409 -1.40722 1.87032</acceleration>
          <wrench>0.009551 -0.005612 -0.001213 0 -0 0</wrench>
        </link>
      </model>
      <model name='trash_lid_hole_2'>
        <pose frame=''>1.7469 -0.09276 0.24908 -0 1e-06 -0.000234</pose>
        <scale>1 1 1</scale>
        <link name='link_0'>
          <pose frame=''>1.73982 -0.090978 0.498163 -0 1e-06 -0.000234</pose>
          <velocity>0.000363 0.000182 -0.003201 -0.000365 0.000728 -1e-06</velocity>
          <acceleration>-0.007431 0.003774 -9.80164 0.000433 0.000632 0.005336</acceleration>
          <wrench>-0.007431 0.003774 -9.80164 0 -0 0</wrench>
        </link>
        <link name='link_1'>
          <pose frame=''>1.75397 -0.094541 -3e-06 -0 1e-06 -0.000234</pose>
          <velocity>7e-06 -4e-06 -0.003209 -0.00036 0.000739 -5e-06</velocity>
          <acceleration>0.007431 -0.003774 -9.79836 0.010883 0.021717 -0.005174</acceleration>
          <wrench>0.007431 -0.003774 -9.79836 0 -0 0</wrench>
        </link>
      </model>
      <light name='sun'>
        <pose frame=''>0 0 10 0 -0 0</pose>
      </light>
    </state>
    <gui fullscreen='0'>
      <camera name='user_camera'>
        <pose frame=''>5 -5 2 0 0.275643 2.35619</pose>
        <view_controller>orbit</view_controller>
        <projection_type>perspective</projection_type>
      </camera>
    </gui>
  </world>
</sdf>
